<?xml version="1.0" ?>
<!-- =================================================================================== -->
<!-- |    This document was autogenerated by xacro from src/libertech_mobile_manipulation/libertech_ranger_arm_description/urdf/ranger_arm.xacro | -->
<!-- |    EDITING THIS FILE BY HAND IS NOT RECOMMENDED                                 | -->
<!-- =================================================================================== -->
<!--
Software License Agreement (BSD)

\file      ranger_mini_v2.urdf
\authors   Achala Athukorala <chhathuranga@gmail.com>
\copyright Copyright (c) 2024, Singapore University of Technology and Design

Redistribution and use in source and binary forms, with or without modification, are permitted provided that
the following conditions are met
 * Redistributions of source code must retain the above copyright notice, this list of conditions and the
   following disclaimer.
 * Redistributions in binary form must reproduce the above copyright notice, this list of conditions and the
   following disclaimer in the documentation and/or other materials provided with the distribution.
 * Neither the name of Clearpath Robotics nor the names of its contributors may be used to endorse or promote
   products derived from this software without specific prior written permission.

THIS SOFTWARE IS PROVIDED BY THE COPYRIGHT HOLDERS AND CONTRIBUTORS "AS IS" AND ANY EXPRESS OR IMPLIED WAR-
RANTIES, INCLUDING, BUT NOT LIMITED TO, THE IMPLIED WARRANTIES OF MERCHANTABILITY AND FITNESS FOR A PARTICULAR
PURPOSE ARE DISCLAIMED. IN NO EVENT SHALL THE COPYRIGHT HOLDER OR CONTRIBUTORS BE LIABLE FOR ANY DIRECT, IN-
DIRECT, INCIDENTAL, SPECIAL, EXEMPLARY, OR CONSEQUENTIAL DAMAGES (INCLUDING, BUT NOT LIMITED TO, PROCUREMENT
OF SUBSTITUTE GOODS OR SERVICES; LOSS OF USE, DATA, OR PROFITS; OR BUSINESS INTERRUPTION) HOWEVER CAUSED AND
ON ANY THEORY OF LIABILITY, WHETHER IN CONTRACT, STRICT LIABILITY, OR TORT (INCLUDING NEGLIGENCE OR OTHERWISE)
ARISING IN ANY WAY OUT OF THE USE OF THIS SOFTWARE, EVEN IF ADVISED OF THE POSSIBILITY OF SUCH DAMAGE.
-->
<!-- Ranger Mini V2 Mobile Base -->
<robot name="ranger_arm">
  <!-- Sensors -->
  <material name="black">
    <color rgba="0.0 0.0 0.0 1.0"/>
  </material>
  <material name="blue">
    <color rgba="0.0 0.0 0.8 1.0"/>
  </material>
  <material name="green">
    <color rgba="0.0 0.8 0.0 1.0"/>
  </material>
  <material name="grey">
    <color rgba="0.2 0.2 0.2 1.0"/>
  </material>
  <material name="grey_alpha">
    <color rgba="0.2 0.2 0.2 0.5"/>
  </material>
  <material name="silver">
    <color rgba="0.9137254901960784 0.9137254901960784 0.8470588235294118 1.0"/>
  </material>
  <material name="orange">
    <color rgba="1.0 0.4235294117647059 0.0392156862745098 1.0"/>
  </material>
  <material name="orange_alpha">
    <color rgba="1.0 0.4235294117647059 0.0392156862745098 0.85"/>
  </material>
  <material name="brown">
    <color rgba="0.8705882352941177 0.8117647058823529 0.7647058823529411 1.0"/>
  </material>
  <material name="red">
    <color rgba="0.8 0.0 0.0 1.0"/>
  </material>
  <material name="white_alpha">
    <color rgba="1.0 1.0 1.0 0.5"/>
  </material>
  <material name="white">
    <color rgba="1.0 1.0 1.0 1.0"/>
  </material>
  <link name="base_footprint"/>
  <joint name="base_link_joint" type="fixed">
    <origin xyz="0 0 0.28"/>
    <parent link="base_footprint"/>
    <child link="base_link"/>
  </joint>
  <link name="base_link">
    <inertial>
      <origin xyz="0.0 0.0 0.0"/>
      <mass value="20"/>
      <inertia ixx="1" ixy="0.0" ixz="0.0" iyy="1" iyz="0.0" izz="1"/>
    </inertial>
    <visual>
      <origin rpy="1.57 0 3.14 " xyz="0 0 0"/>
      <geometry>
        <mesh filename="file:///home/ccs/ros2/teleop_ws/install/libertech_ranger_arm_description/share/libertech_ranger_arm_description/meshes/ranger_mini_v2/ranger_base.dae"/>
      </geometry>
    </visual>
    <collision>
      <origin rpy="0 0 0" xyz="0 0 -0.1"/>
      <geometry>
        <box size="0.5 0.35 0.2"/>
      </geometry>
    </collision>
  </link>
  <link name="fl_steering_wheel_link">
    <inertial>
      <origin xyz="0.0 0.0 0.0"/>
      <mass value="1"/>
      <inertia ixx="0.01" ixy="0.0" ixz="0.0" iyy="0.01" iyz="0.0" izz="0.01"/>
    </inertial>
    <visual>
      <origin rpy="1.57 0 3.14 " xyz="-0.23 -0.194 0.1"/>
      <geometry>
        <mesh filename="file:///home/ccs/ros2/teleop_ws/install/libertech_ranger_arm_description/share/libertech_ranger_arm_description/meshes/ranger_mini_v2/fl.dae"/>
      </geometry>
    </visual>
    <collision>
      <origin rpy="0 0 0" xyz="0 0 0.008"/>
      <geometry>
        <cylinder length="0.001" radius="0.001"/>
      </geometry>
    </collision>
  </link>
  <joint name="fl_steering_wheel" type="revolute">
    <origin rpy="0 0 0" xyz="0.23 0.206 -0.1"/>
    <parent link="base_link"/>
    <child link="fl_steering_wheel_link"/>
    <axis rpy="0 0 0" xyz="0 0 1"/>
    <limit effort="5" lower="-2.1" upper="2.1" velocity="1"/>
  </joint>
  <link name="fl_wheel_link">
    <inertial>
      <mass value="8"/>
      <origin xyz="0 0 0"/>
      <inertia ixx="0.1171" ixy="0" ixz="0" iyy="0.1361" iyz="0" izz="0.1171"/>
    </inertial>
    <visual>
      <origin rpy="1.57 0 0" xyz="0 0 0"/>
      <geometry>
        <cylinder length="0.01" radius="0.01"/>
      </geometry>
    </visual>
    <collision>
      <origin rpy="1.57 0 0" xyz="0 0 0"/>
      <geometry>
        <cylinder length="0.08" radius="0.08"/>
      </geometry>
      <contact>
        <ode>
          <min_depth>0.001</min_depth>
        </ode>
      </contact>
    </collision>
  </link>
  <joint name="fl_wheel" type="continuous">
    <origin rpy="0 0 0" xyz="0.00 0.00 -0.12"/>
    <parent link="fl_steering_wheel_link"/>
    <child link="fl_wheel_link"/>
    <axis rpy="0 0 0" xyz="0 1 0"/>
  </joint>
  <link name="fr_steering_wheel_link">
    <inertial>
      <origin rpy="0.0 0.0 0.0" xyz="0.0 0.0 0.0"/>
      <mass value="1"/>
      <inertia ixx="0.01" ixy="0.0" ixz="0.0" iyy="0.01" iyz="0.0" izz="0.01"/>
    </inertial>
    <visual>
      <origin rpy="1.57 0 3.14 " xyz="-0.23 0.194 0.1"/>
      <geometry>
        <mesh filename="file:///home/ccs/ros2/teleop_ws/install/libertech_ranger_arm_description/share/libertech_ranger_arm_description/meshes/ranger_mini_v2/fr.dae"/>
      </geometry>
    </visual>
    <collision>
      <origin rpy="0 0 0" xyz="0 0 0.008"/>
      <geometry>
        <cylinder length="0.001" radius="0.001"/>
      </geometry>
    </collision>
  </link>
  <joint name="fr_steering_wheel" type="revolute">
    <origin rpy="0 0 0" xyz="0.23 -0.206 -0.1"/>
    <parent link="base_link"/>
    <child link="fr_steering_wheel_link"/>
    <axis rpy="0 0 0" xyz="0 0 1"/>
    <limit effort="5" lower="-2.1" upper="2.1" velocity="1"/>
  </joint>
  <link name="fr_wheel_link">
    <inertial>
      <mass value="8"/>
      <origin xyz="0 0 0"/>
      <inertia ixx="0.1171" ixy="0" ixz="0" iyy="0.1361" iyz="0" izz="0.1171"/>
    </inertial>
    <visual>
      <origin rpy="1.57 0 0" xyz="0 0 0"/>
      <geometry>
        <cylinder length="0.01" radius="0.01"/>
      </geometry>
    </visual>
    <collision>
      <origin rpy="1.57 0 0" xyz="0 0 0"/>
      <geometry>
        <cylinder length="0.08" radius="0.08"/>
      </geometry>
      <contact>
        <ode>
          <min_depth>0.001</min_depth>
        </ode>
      </contact>
    </collision>
  </link>
  <joint name="fr_wheel" type="continuous">
    <origin rpy="0 0 0" xyz="0.0 0.0 -0.12"/>
    <parent link="fr_steering_wheel_link"/>
    <child link="fr_wheel_link"/>
    <axis rpy="0 0 0" xyz="0 1 0"/>
  </joint>
  <link name="rl_steering_wheel_link">
    <inertial>
      <origin rpy="0.0 0.0 0.0" xyz="0.0 0.0 0.0"/>
      <mass value="1"/>
      <inertia ixx="0.01" ixy="0.0" ixz="0.0" iyy="0.01" iyz="0.0" izz="0.01"/>
    </inertial>
    <visual>
      <origin rpy="1.57 0 3.14 " xyz="-0.23 -0.194 0.1"/>
      <geometry>
        <mesh filename="file:///home/ccs/ros2/teleop_ws/install/libertech_ranger_arm_description/share/libertech_ranger_arm_description/meshes/ranger_mini_v2/fl.dae"/>
      </geometry>
    </visual>
    <collision>
      <origin rpy="0 0 0" xyz="0 0 0.008"/>
      <geometry>
        <cylinder length="0.001" radius="0.001"/>
      </geometry>
    </collision>
  </link>
  <joint name="rl_steering_wheel" type="revolute">
    <origin rpy="0 0 0" xyz="-0.23 0.206 -0.1"/>
    <parent link="base_link"/>
    <child link="rl_steering_wheel_link"/>
    <axis rpy="0 0 0" xyz="0 0 1"/>
    <limit effort="5" lower="-2.1" upper="2.1" velocity="1"/>
  </joint>
  <link name="rl_wheel_link">
    <inertial>
      <mass value="8"/>
      <origin xyz="0 0 0"/>
      <inertia ixx="0.1171" ixy="0" ixz="0" iyy="0.1361" iyz="0" izz="0.1171"/>
    </inertial>
    <visual>
      <origin rpy="1.57 0 0" xyz="0 0 0"/>
      <geometry>
        <cylinder length="0.01" radius="0.01"/>
      </geometry>
    </visual>
    <collision>
      <origin rpy="1.57 0 0" xyz="0 0 0"/>
      <geometry>
        <cylinder length="0.08" radius="0.08"/>
      </geometry>
      <contact>
        <ode>
          <min_depth>0.001</min_depth>
        </ode>
      </contact>
    </collision>
  </link>
  <joint name="rl_wheel" type="continuous">
    <origin rpy="0 0 0" xyz="0.0 0.0 -0.12 "/>
    <parent link="rl_steering_wheel_link"/>
    <child link="rl_wheel_link"/>
    <axis rpy="0 0 0" xyz="0 1 0"/>
  </joint>
  <link name="rr_steering_wheel_link">
    <inertial>
      <origin xyz="0.0 0.0 0.0"/>
      <mass value="1"/>
      <inertia ixx="0.01" ixy="0.0" ixz="0.0" iyy="0.01" iyz="0.0" izz="0.01"/>
    </inertial>
    <visual>
      <origin rpy="1.57 0 3.14 " xyz="-0.23 0.194 0.1"/>
      <geometry>
        <mesh filename="file:///home/ccs/ros2/teleop_ws/install/libertech_ranger_arm_description/share/libertech_ranger_arm_description/meshes/ranger_mini_v2/fr.dae"/>
      </geometry>
    </visual>
    <collision>
      <origin rpy="0 0 0" xyz="0 0 0.008"/>
      <geometry>
        <cylinder length="0.001" radius="0.001"/>
      </geometry>
    </collision>
  </link>
  <joint name="rr_steering_wheel" type="revolute">
    <origin rpy="0 0 0" xyz="-0.23 -0.206 -0.1"/>
    <parent link="base_link"/>
    <child link="rr_steering_wheel_link"/>
    <axis rpy="0 0 0" xyz="0 0 1"/>
    <limit effort="5" lower="-2.1" upper="2.1" velocity="1"/>
  </joint>
  <link name="rr_wheel_link">
    <inertial>
      <mass value="8"/>
      <origin xyz="0 0 0"/>
      <inertia ixx="0.1171" ixy="0" ixz="0" iyy="0.1361" iyz="0" izz="0.1171"/>
    </inertial>
    <visual>
      <origin rpy="1.57 0 0" xyz="0.0 0.0 0.0"/>
      <geometry>
        <cylinder length="0.01" radius="0.01"/>
      </geometry>
    </visual>
    <collision>
      <origin rpy="1.57 0 0" xyz="0 0 0"/>
      <geometry>
        <cylinder length="0.08" radius="0.08"/>
      </geometry>
      <contact>
        <ode>
          <min_depth>0.001</min_depth>
        </ode>
      </contact>
    </collision>
  </link>
  <joint name="rr_wheel" type="continuous">
    <origin rpy="0 0 0" xyz="0.0 0.0 -0.12 "/>
    <parent link="rr_steering_wheel_link"/>
    <child link="rr_wheel_link"/>
    <axis rpy="0 0 0" xyz="0 1 0"/>
  </joint>
  <gazebo reference="fl_wheel_link">
    <collision>
      <surface>
        <friction>
          <ode>
            <mu>0.1</mu>
            <mu2>0.1</mu2>
          </ode>
        </friction>
        <contact>
          <ode>
            <kp>50000.0</kp>
            <kd>10.0</kd>
          </ode>
        </contact>
      </surface>
    </collision>
    <!-- <minDepth>0.001</minDepth>
            <maxVel>0.1</maxVel>
            <fdir1>1 0 0</fdir1> -->
  </gazebo>
  <gazebo reference="fr_wheel_link">
    <collision>
      <surface>
        <friction>
          <ode>
            <mu>0.1</mu>
            <mu2>0.1</mu2>
          </ode>
        </friction>
        <contact>
          <ode>
            <kp>50000.0</kp>
            <kd>10.0</kd>
          </ode>
        </contact>
      </surface>
    </collision>
    <!-- <minDepth>0.001</minDepth>
            <maxVel>0.1</maxVel>
            <fdir1>1 0 0</fdir1> -->
  </gazebo>
  <gazebo reference="rl_wheel_link">
    <collision>
      <surface>
        <friction>
          <ode>
            <mu>0.1</mu>
            <mu2>0.1</mu2>
          </ode>
        </friction>
        <contact>
          <ode>
            <kp>50000.0</kp>
            <kd>10.0</kd>
          </ode>
        </contact>
      </surface>
    </collision>
    <!-- <minDepth>0.001</minDepth>
            <maxVel>0.1</maxVel>
            <fdir1>1 0 0</fdir1> -->
  </gazebo>
  <gazebo reference="rr_wheel_link">
    <collision>
      <surface>
        <friction>
          <ode>
            <mu>0.1</mu>
            <mu2>0.1</mu2>
          </ode>
        </friction>
        <contact>
          <ode>
            <kp>50000.0</kp>
            <kd>10.0</kd>
          </ode>
        </contact>
      </surface>
    </collision>
    <!-- <minDepth>0.001</minDepth>
            <maxVel>0.1</maxVel>
            <fdir1>1 0 0</fdir1> -->
  </gazebo>
  <!-- Sensors -->
  <link name="base_add_on">
    <inertial>
      <origin rpy="0 0 0" xyz="0.0455338389926168 -0.00103634765767435 0.220800927413883"/>
      <mass value="6.44138353782306"/>
      <inertia ixx="0.0992945121069776" ixy="5.84470364161191E-05" ixz="-4.71376239762533E-07" iyy="0.124094455743998" iyz="1.23371057479671E-08" izz="0.13752951719075"/>
    </inertial>
    <visual>
      <origin rpy="0 0 0" xyz="0 0 0"/>
      <geometry>
        <mesh filename="file:///home/ccs/ros2/teleop_ws/install/libertech_ranger_arm_description/share/libertech_ranger_arm_description/meshes/ranger_mini_v2/base_add_on.STL"/>
      </geometry>
      <material name="">
        <color rgba="0.792156862745098 0.819607843137255 0.933333333333333 1"/>
      </material>
    </visual>
    <collision>
      <origin rpy="0 0 0" xyz="0 0 0"/>
      <geometry>
        <mesh filename="file:///home/ccs/ros2/teleop_ws/install/libertech_ranger_arm_description/share/libertech_ranger_arm_description/meshes/ranger_mini_v2/base_add_on.STL"/>
      </geometry>
    </collision>
  </link>
  <joint name="base_joint" type="fixed">
    <origin rpy="0 0 0" xyz="0.015 0.0 0.024"/>
    <parent link="base_link"/>
    <child link="base_add_on"/>
  </joint>
  <link name="lidar_link"/>
  <joint name="lidar_joint" type="fixed">
    <parent link="base_add_on"/>
    <child link="lidar_link"/>
    <origin rpy="0 0 0" xyz="0.23523 0 0.6"/>
  </joint>
  <!-- 实际正放在上 -->
  <!-- 期望前置 -->
  <link name="imu_link">
    <inertial>
      <mass value="0.01"/>
      <origin rpy="0 0 0" xyz="0 0 0"/>
      <inertia ixx="0.000001" ixy="0" ixz="0" iyy="0.000001" iyz="0" izz="0.000001"/>
    </inertial>
    <!-- <visual>
            <origin rpy="0 0 0" xyz="0 0 0"/>
            <geometry>
                <box size="0.015 0.015 0.004"/>
            </geometry>
        </visual> -->
  </link>
  <joint name="imu_joint" type="fixed">
    <origin rpy="0 0 0" xyz="0.0 0 0.0"/>
    <parent link="lidar_link"/>
    <child link="imu_link"/>
  </joint>
  <link name="camera_link"/>
  <joint name="camera_joint" type="fixed">
    <parent link="base_add_on"/>
    <child link="camera_link"/>
    <origin rpy="0 0 0" xyz="0.34 0 0.55"/>
  </joint>
  <link name="camera_optical_frame"/>
  <joint name="camera_optical_joint" type="fixed">
    <origin rpy="-1.5707963267948966 0.0 -1.5707963267948966" xyz="0 0 0"/>
    <parent link="camera_link"/>
    <child link="camera_optical_frame"/>
  </joint>
  <gazebo reference="imu_link">
    <sensor name="imu_link_imu" type="imu">
      <visualize>true</visualize>
      <topic>imu</topic>
      <ignition_frame_id>imu_link</ignition_frame_id>
      <always_on>true</always_on>
      <update_rate>100</update_rate>
      <imu>
        <angular_velocity>
          <x>
            <noise type="gaussian">
              <mean>0.0</mean>
              <stddev>0.0</stddev>
            </noise>
          </x>
          <y>
            <noise type="gaussian">
              <mean>0.0</mean>
              <stddev>0.0</stddev>
            </noise>
          </y>
          <z>
            <noise type="gaussian">
              <mean>0.0</mean>
              <stddev>0.0</stddev>
            </noise>
          </z>
        </angular_velocity>
        <linear_acceleration>
          <x>
            <noise type="gaussian">
              <mean>0.0</mean>
              <stddev>0.0</stddev>
            </noise>
          </x>
          <y>
            <noise type="gaussian">
              <mean>0.0</mean>
              <stddev>0.0</stddev>
            </noise>
          </y>
          <z>
            <noise type="gaussian">
              <mean>0.0</mean>
              <stddev>0.0</stddev>
            </noise>
          </z>
        </linear_acceleration>
      </imu>
    </sensor>
  </gazebo>
  <gazebo reference="imu_joint">
    <preserveFixedJoint>true</preserveFixedJoint>
    <disableFixedJointLumping>true</disableFixedJointLumping>
  </gazebo>
  <gazebo reference="lidar_link">
    <sensor name="lidar_link_lidar" type="gpu_lidar">
      <!--
                    Move the sensor up slightly from the bottom of the lidar unit.
                -->
      <pose>0 0 0.03 0 0 0</pose>
      <alwaysOn>true</alwaysOn>
      <topic>scan</topic>
      <update_rate>10</update_rate>
      <visualize>true</visualize>
      <ignition_frame_id>lidar_link</ignition_frame_id>
      <ray>
        <scan>
          <horizontal>
            <samples>640</samples>
            <resolution>1.0</resolution>
            <min_angle>0</min_angle>
            <max_angle>6.28</max_angle>
          </horizontal>
          <vertical>
            <samples>1</samples>
            <resolution>1</resolution>
            <min_angle>0</min_angle>
            <max_angle>0</max_angle>
          </vertical>
        </scan>
        <range>
          <min>0.164</min>
          <max>12.0</max>
          <resolution>0.01</resolution>
        </range>
      </ray>
    </sensor>
  </gazebo>
  <gazebo reference="camera_link">
    <sensor name="camera_link_camera" type="rgbd_camera">
      <camera>
        <horizontal_fov>1.047</horizontal_fov>
        <image>
          <width>640</width>
          <height>480</height>
          <format>R8G8B8</format>
          <!-- RGB_INT8 -->
        </image>
        <clip>
          <near>0.02</near>
          <far>20</far>
        </clip>
        <distortion>
          <k1>0.0</k1>
          <k2>0.0</k2>
          <k3>0.0</k3>
          <p1>0.0</p1>
          <p2>0.0</p2>
          <center>0.5 0.5</center>
        </distortion>
        <lens>
          <intrinsics>
            <fx>554.25469</fx>
            <!-- fx = fy = width / ( 2 * tan (hfov / 2 ) ) -->
            <fy>554.25469</fy>
            <cx>320.5</cx>
            <!-- cx = ( width + 1 ) / 2 -->
            <cy>240.5</cy>
            <!-- cy = ( height + 1 ) / 2 -->
            <s>0</s>
          </intrinsics>
          <!-- These need to match the intrinsics above or
                            Ignition will default to different default values -->
          <projection>
            <p_fx>554.25469</p_fx>
            <p_fy>554.25469</p_fy>
            <p_cx>320.5</p_cx>
            <p_cy>240.5</p_cy>
            <tx>0</tx>
            <ty>0</ty>
          </projection>
        </lens>
        <!-- <noise>
                        <type>gaussian</type>
                        <mean>0</mean>
                        <stddev>0.07</stddev>
                    </noise> -->
        <depth_camera>
          <clip>
            <near>0.25</near>
            <far>5</far>
          </clip>
        </depth_camera>
        <!-- <optical_frame_id>${link_name}_optical_frame</optical_frame_id> -->
      </camera>
      <ignition_frame_id>camera_link</ignition_frame_id>
      <always_on>true</always_on>
      <update_rate>30</update_rate>
      <!-- <visualize>true</visualize> -->
      <topic>camera</topic>
      <enable_metrics>false</enable_metrics>
    </sensor>
  </gazebo>
  <joint name="base_add_on_to_arm_right_fixed" type="fixed">
    <origin rpy="-1.5708 0 -3.1416" xyz="0.23523 -0.16811 0.4925"/>
    <parent link="base_add_on"/>
    <child link="arm_right_link0"/>
  </joint>
  <link name="arm_right_link0">
    <inertial>
      <origin rpy="0 0 0" xyz="0.00015789 1.1425E-05 -0.026926"/>
      <mass value="0.057424"/>
      <inertia ixx="3.4494E-05" ixy="-8.7249E-09" ixz="1.5443E-08" iyy="3.4241E-05" iyz="3.5354E-09" izz="6.5635E-05"/>
    </inertial>
    <visual>
      <origin rpy="0 0 0" xyz="0 0 0"/>
      <geometry>
        <mesh filename="file:///home/ccs/ros2/teleop_ws/install/libertech_ranger_arm_description/share/libertech_ranger_arm_description/meshes/arm/link0.STL"/>
      </geometry>
      <material name="">
        <color rgba="0.79216 0.81961 0.93333 1"/>
      </material>
    </visual>
    <collision>
      <origin rpy="0 0 0" xyz="0 0 0"/>
      <geometry>
        <mesh filename="file:///home/ccs/ros2/teleop_ws/install/libertech_ranger_arm_description/share/libertech_ranger_arm_description/meshes/arm/link0.STL"/>
      </geometry>
    </collision>
  </link>
  <link name="arm_right_link1">
    <inertial>
      <origin rpy="0 0 0" xyz="0.0067996 -8.3556E-09 0.02733"/>
      <mass value="0.10407"/>
      <inertia ixx="8.2311E-05" ixy="1.9979E-10" ixz="-1.0236E-05" iyy="0.00018185" iyz="-5.5152E-12" izz="0.00017098"/>
    </inertial>
    <visual>
      <origin rpy="0 0 0" xyz="0 0 0"/>
      <geometry>
        <mesh filename="file:///home/ccs/ros2/teleop_ws/install/libertech_ranger_arm_description/share/libertech_ranger_arm_description/meshes/arm/link1.STL"/>
      </geometry>
      <material name="">
        <color rgba="0.59804 0.91765 0.92941 1"/>
      </material>
    </visual>
    <collision>
      <origin rpy="0 0 0" xyz="0 0 0"/>
      <geometry>
        <mesh filename="file:///home/ccs/ros2/teleop_ws/install/libertech_ranger_arm_description/share/libertech_ranger_arm_description/meshes/arm/link1.STL"/>
      </geometry>
    </collision>
  </link>
  <joint name="arm_right_joint1" type="revolute">
    <origin rpy="0 0 0" xyz="0 0 0"/>
    <parent link="arm_right_link0"/>
    <child link="arm_right_link1"/>
    <axis xyz="0 0 1"/>
    <limit effort="45.0" lower="-1.2217304763960306" upper="2.443460952792061" velocity="3.490658503988659"/>
  </joint>
  <link name="arm_right_link2">
    <inertial>
      <origin rpy="0 0 0" xyz="-0.00010195 0.083732 -0.00067262"/>
      <mass value="0.23039"/>
      <inertia ixx="0.00041883" ixy="-5.1421E-08" ixz="7.7215E-09" iyy="0.00018974" iyz="6.3393E-06" izz="0.00050303"/>
    </inertial>
    <visual>
      <origin rpy="0 0 0" xyz="0 0 0"/>
      <geometry>
        <mesh filename="file:///home/ccs/ros2/teleop_ws/install/libertech_ranger_arm_description/share/libertech_ranger_arm_description/meshes/arm/link2.STL"/>
      </geometry>
      <material name="">
        <color rgba="0.79216 0.81961 0.93333 1"/>
      </material>
    </visual>
    <collision>
      <origin rpy="0 0 0" xyz="0 0 0"/>
      <geometry>
        <mesh filename="file:///home/ccs/ros2/teleop_ws/install/libertech_ranger_arm_description/share/libertech_ranger_arm_description/meshes/arm/link2.STL"/>
      </geometry>
    </collision>
  </link>
  <joint name="arm_right_joint2" type="revolute">
    <origin rpy="1.5708 0 1.5708" xyz="0 0 0.062"/>
    <parent link="arm_right_link1"/>
    <child link="arm_right_link2"/>
    <axis xyz="0 0 1"/>
    <limit effort="45.0" lower="-1.5707963267948966" upper="1.3962634015954636" velocity="3.490658503988659"/>
  </joint>
  <link name="arm_right_link3">
    <inertial>
      <origin rpy="0 0 0" xyz="0.0058456 -0.0011149 0.26476"/>
      <mass value="0.098445"/>
      <inertia ixx="7.7802E-05" ixy="1.0294e-06" ixz="-1.0177e-05" iyy="0.00011471" iyz="1.6629E-07" izz="6.9147E-05"/>
    </inertial>
    <visual>
      <origin rpy="0 0 0" xyz="0 0 0"/>
      <geometry>
        <mesh filename="file:///home/ccs/ros2/teleop_ws/install/libertech_ranger_arm_description/share/libertech_ranger_arm_description/meshes/arm/link3.STL" scale="1 1 1"/>
      </geometry>
      <material name="">
        <color rgba="0.79216 0.81961 0.93333 1"/>
      </material>
    </visual>
    <!-- <collision>
				<origin xyz="0 0 0" rpy="0 0 0" />
				<geometry>
					<mesh filename="${mesh_visual_path}/arm/link3.STL" scale="${reverse} 1 1"/>
				</geometry>
			</collision> -->
  </link>
  <joint name="arm_right_joint3" type="revolute">
    <origin rpy="-1.5708 0 0" xyz="0 0 0"/>
    <parent link="arm_right_link2"/>
    <child link="arm_right_link3"/>
    <axis xyz="0 0 1"/>
    <limit effort="45.0" lower="-2.9670597283903604" upper="-0.17453292519943295" velocity="3.490658503988659"/>
  </joint>
  <link name="arm_right_link4">
    <inertial>
      <origin rpy="0 0 0" xyz="-1.2044E-08 0.027148 -0.0065686"/>
      <mass value="0.083265"/>
      <inertia ixx="9.7154E-05" ixy="8.5996E-12" ixz="-1.0835E-10" iyy="9.5206E-05" iyz="-6.2319E-06" izz="5.8053E-05"/>
    </inertial>
    <visual>
      <origin rpy="0 0 0" xyz="0 0 0"/>
      <geometry>
        <mesh filename="file:///home/ccs/ros2/teleop_ws/install/libertech_ranger_arm_description/share/libertech_ranger_arm_description/meshes/arm/link4.STL"/>
      </geometry>
      <material name="">
        <color rgba="0.89804 0.91765 0.92941 1"/>
      </material>
    </visual>
    <collision>
      <origin rpy="0 0 0" xyz="0 0 0"/>
      <geometry>
        <mesh filename="file:///home/ccs/ros2/teleop_ws/install/libertech_ranger_arm_description/share/libertech_ranger_arm_description/meshes/arm/link4.STL"/>
      </geometry>
    </collision>
  </link>
  <joint name="arm_right_joint4" type="revolute">
    <origin rpy="1.5708 0 0" xyz="0 0 0.27"/>
    <parent link="arm_right_link3"/>
    <child link="arm_right_link4"/>
    <axis xyz="0 0 1"/>
    <limit effort="45.0" lower="0.0" upper="1.8325957145940461" velocity="3.490658503988659"/>
  </joint>
  <link name="arm_right_link5">
    <inertial>
      <origin rpy="0 0 0" xyz="5.7592E-05 0.0030098 0.11674"/>
      <mass value="0.10135"/>
      <inertia ixx="0.00011025" ixy="5.7106E-09" ixz="-2.863E-08" iyy="0.00013727" iyz="-1.4278E-06" izz="4.6819E-05"/>
    </inertial>
    <visual>
      <origin rpy="0 0 0" xyz="0 0 0"/>
      <geometry>
        <mesh filename="file:///home/ccs/ros2/teleop_ws/install/libertech_ranger_arm_description/share/libertech_ranger_arm_description/meshes/arm/link5.STL"/>
      </geometry>
      <material name="">
        <color rgba="0.59216 0.81961 0.93333 1"/>
      </material>
    </visual>
    <collision>
      <origin rpy="0 0 0" xyz="0 0 0"/>
      <geometry>
        <mesh filename="file:///home/ccs/ros2/teleop_ws/install/libertech_ranger_arm_description/share/libertech_ranger_arm_description/meshes/arm/link5.STL"/>
      </geometry>
    </collision>
  </link>
  <joint name="arm_right_joint5" type="revolute">
    <origin rpy="-1.5708 0 0" xyz="0 0 0"/>
    <parent link="arm_right_link4"/>
    <child link="arm_right_link5"/>
    <axis xyz="0 0 1"/>
    <limit effort="45.0" lower="-1.5707963267948966" upper="1.5707963267948966" velocity="3.490658503988659"/>
  </joint>
  <link name="arm_right_link6">
    <inertial>
      <origin rpy="0 0 0" xyz="-0.00073065 0.035532 -0.0043423"/>
      <mass value="0.069725"/>
      <inertia ixx="3.6856E-05" ixy="6.4441e-06" ixz="3.2959e-06" iyy="3.961E-05" iyz="-7.8545E-06" izz="3.6658E-05"/>
    </inertial>
    <visual>
      <origin rpy="0 0 0" xyz="0 0 0"/>
      <geometry>
        <mesh filename="file:///home/ccs/ros2/teleop_ws/install/libertech_ranger_arm_description/share/libertech_ranger_arm_description/meshes/arm/link6.STL" scale="1 1 1"/>
      </geometry>
      <material name="">
        <color rgba="0.89804 0.61765 0.92941 1"/>
      </material>
    </visual>
    <!-- <collision>
				<origin xyz="0 0 0" rpy="0 0 0" />
				<geometry>
					<mesh filename="${mesh_visual_path}/arm/link6.STL" scale="${reverse} 1 1"/>
				</geometry>
			</collision> -->
  </link>
  <joint name="arm_right_joint6" type="revolute">
    <origin rpy="1.5708 0 0" xyz="0 0 0.157"/>
    <parent link="arm_right_link5"/>
    <child link="arm_right_link6"/>
    <axis xyz="0 0 1"/>
    <limit effort="45.0" lower="-1.3089969389957472" upper="1.3089969389957472" velocity="3.490658503988659"/>
  </joint>
  <link name="arm_right_link7">
    <inertial>
      <origin rpy="0 0 0" xyz="0.031922 0.00073671 0.0014868"/>
      <mass value="0.11565"/>
      <inertia ixx="4.2212E-05" ixy="-9.2648e-09" ixz="1.6154E-06" iyy="3.1231E-05" iyz="3.4989e-09" izz="4.1383E-05"/>
    </inertial>
    <visual>
      <origin rpy="0 0 0" xyz="0 0 0"/>
      <geometry>
        <mesh filename="file:///home/ccs/ros2/teleop_ws/install/libertech_ranger_arm_description/share/libertech_ranger_arm_description/meshes/arm/link7.STL" scale="1 1 1"/>
      </geometry>
      <material name="">
        <color rgba="0.79216 0.81961 0.93333 1"/>
      </material>
    </visual>
    <!-- <collision>
				<origin xyz="0 0 0" rpy="0 0 0" />
				<geometry>
					<mesh filename="${mesh_visual_path}/arm/link7.STL" scale="1 ${reverse} 1" />
				</geometry>
			</collision> -->
  </link>
  <joint name="arm_right_joint7" type="revolute">
    <origin rpy="-1.5708 0 1.5708" xyz="0 0.07 0"/>
    <parent link="arm_right_link6"/>
    <child link="arm_right_link7"/>
    <axis xyz="0 0 -1"/>
    <limit effort="45.0" lower="-0.8726646259971648" upper="0.8726646259971648" velocity="3.490658503988659"/>
  </joint>
  <link name="arm_right_quick_release">
    <inertial>
      <origin rpy="0 0 0" xyz="-0.0046261 0.0032983 0.0069587"/>
      <mass value="0.5"/>
      <inertia ixx="3.5312E-05" ixy="-3.2715E-06" ixz="5.6547E-09" iyy="2.4468E-05" iyz="-2.9526E-09" izz="5.6973E-05"/>
    </inertial>
    <visual>
      <origin rpy="0 0 0" xyz="0 0 0"/>
      <geometry>
        <mesh filename="file:///home/ccs/ros2/teleop_ws/install/libertech_ranger_arm_description/share/libertech_ranger_arm_description/meshes/arm/quick_release.STL"/>
      </geometry>
      <material name="silver"/>
    </visual>
    <collision>
      <origin rpy="0 0 0" xyz="0 0 0"/>
      <geometry>
        <mesh filename="file:///home/ccs/ros2/teleop_ws/install/libertech_ranger_arm_description/share/libertech_ranger_arm_description/meshes/arm/quick_release.STL"/>
      </geometry>
    </collision>
  </link>
  <joint name="arm_right_quick_release_joint" type="fixed">
    <origin rpy="1.5707963267948966 3.141592653589793 1.5707963267948966" xyz="0.0675 0 0"/>
    <parent link="arm_right_link7"/>
    <child link="arm_right_quick_release"/>
    <axis xyz="0 0 0"/>
  </joint>
  <link name="arm_right_flange_link"/>
  <joint name="arm_right_flange_joint" type="fixed">
    <origin rpy="0.0 0.0 0.0 " xyz="0.0675 0 0"/>
    <parent link="arm_right_link7"/>
    <child link="arm_right_flange_link"/>
  </joint>
  <link name="arm_right_tool_link"/>
  <joint name="arm_right_tool_joint" type="fixed">
    <origin rpy="0.0 0.0 0.0 " xyz="0.15 0 0"/>
    <parent link="arm_right_flange_link"/>
    <child link="arm_right_tool_link"/>
  </joint>
  <link name="arm_right_rokubi_ft_link"/>
  <joint name="arm_right_rokubi_ft_joint" type="fixed">
    <origin rpy="3.141592653589793 -1.5707963267948966 0.0 " xyz="0.0295 0 0"/>
    <parent link="arm_right_link7"/>
    <child link="arm_right_rokubi_ft_link"/>
  </joint>
  <link name="arm_right_rokubi_ft_wrench_link"/>
  <joint name="arm_right_rokubi_ft_wrench_joint" type="fixed">
    <origin rpy="0 0 0" xyz="0 0 0.032"/>
    <parent link="arm_right_rokubi_ft_link"/>
    <child link="arm_right_rokubi_ft_wrench_link"/>
  </joint>
  <joint name="base_add_on_to_arm_left_fixed" type="fixed">
    <origin rpy="1.5708 0 -3.1416" xyz="0.23523 0.16811 0.4925"/>
    <parent link="base_add_on"/>
    <child link="arm_left_link0"/>
  </joint>
  <link name="arm_left_link0">
    <inertial>
      <origin rpy="0 0 0" xyz="0.00015789 1.1425E-05 -0.026926"/>
      <mass value="0.057424"/>
      <inertia ixx="3.4494E-05" ixy="-8.7249E-09" ixz="1.5443E-08" iyy="3.4241E-05" iyz="3.5354E-09" izz="6.5635E-05"/>
    </inertial>
    <visual>
      <origin rpy="0 0 0" xyz="0 0 0"/>
      <geometry>
        <mesh filename="file:///home/ccs/ros2/teleop_ws/install/libertech_ranger_arm_description/share/libertech_ranger_arm_description/meshes/arm/link0.STL"/>
      </geometry>
      <material name="">
        <color rgba="0.79216 0.81961 0.93333 1"/>
      </material>
    </visual>
    <collision>
      <origin rpy="0 0 0" xyz="0 0 0"/>
      <geometry>
        <mesh filename="file:///home/ccs/ros2/teleop_ws/install/libertech_ranger_arm_description/share/libertech_ranger_arm_description/meshes/arm/link0.STL"/>
      </geometry>
    </collision>
  </link>
  <link name="arm_left_link1">
    <inertial>
      <origin rpy="0 0 0" xyz="0.0067996 -8.3556E-09 0.02733"/>
      <mass value="0.10407"/>
      <inertia ixx="8.2311E-05" ixy="1.9979E-10" ixz="-1.0236E-05" iyy="0.00018185" iyz="-5.5152E-12" izz="0.00017098"/>
    </inertial>
    <visual>
      <origin rpy="0 0 0" xyz="0 0 0"/>
      <geometry>
        <mesh filename="file:///home/ccs/ros2/teleop_ws/install/libertech_ranger_arm_description/share/libertech_ranger_arm_description/meshes/arm/link1.STL"/>
      </geometry>
      <material name="">
        <color rgba="0.59804 0.91765 0.92941 1"/>
      </material>
    </visual>
    <collision>
      <origin rpy="0 0 0" xyz="0 0 0"/>
      <geometry>
        <mesh filename="file:///home/ccs/ros2/teleop_ws/install/libertech_ranger_arm_description/share/libertech_ranger_arm_description/meshes/arm/link1.STL"/>
      </geometry>
    </collision>
  </link>
  <joint name="arm_left_joint1" type="revolute">
    <origin rpy="0 0 0" xyz="0 0 0"/>
    <parent link="arm_left_link0"/>
    <child link="arm_left_link1"/>
    <axis xyz="0 0 -1"/>
    <limit effort="45.0" lower="-1.2217304763960306" upper="2.443460952792061" velocity="3.490658503988659"/>
  </joint>
  <link name="arm_left_link2">
    <inertial>
      <origin rpy="0 0 0" xyz="-0.00010195 0.083732 -0.00067262"/>
      <mass value="0.23039"/>
      <inertia ixx="0.00041883" ixy="-5.1421E-08" ixz="7.7215E-09" iyy="0.00018974" iyz="6.3393E-06" izz="0.00050303"/>
    </inertial>
    <visual>
      <origin rpy="0 0 0" xyz="0 0 0"/>
      <geometry>
        <mesh filename="file:///home/ccs/ros2/teleop_ws/install/libertech_ranger_arm_description/share/libertech_ranger_arm_description/meshes/arm/link2.STL"/>
      </geometry>
      <material name="">
        <color rgba="0.79216 0.81961 0.93333 1"/>
      </material>
    </visual>
    <collision>
      <origin rpy="0 0 0" xyz="0 0 0"/>
      <geometry>
        <mesh filename="file:///home/ccs/ros2/teleop_ws/install/libertech_ranger_arm_description/share/libertech_ranger_arm_description/meshes/arm/link2.STL"/>
      </geometry>
    </collision>
  </link>
  <joint name="arm_left_joint2" type="revolute">
    <origin rpy="1.5708 0 1.5708" xyz="0 0 0.062"/>
    <parent link="arm_left_link1"/>
    <child link="arm_left_link2"/>
    <axis xyz="0 0 -1"/>
    <limit effort="45.0" lower="-1.5707963267948966" upper="1.3962634015954636" velocity="3.490658503988659"/>
  </joint>
  <link name="arm_left_link3">
    <inertial>
      <origin rpy="0 0 0" xyz="0.0058456 -0.0011149 0.26476"/>
      <mass value="0.098445"/>
      <inertia ixx="7.7802E-05" ixy="-1.0294e-06" ixz="1.0177e-05" iyy="0.00011471" iyz="1.6629E-07" izz="6.9147E-05"/>
    </inertial>
    <visual>
      <origin rpy="0 0 0" xyz="0 0 0"/>
      <geometry>
        <mesh filename="file:///home/ccs/ros2/teleop_ws/install/libertech_ranger_arm_description/share/libertech_ranger_arm_description/meshes/arm/link3.STL" scale="-1 1 1"/>
      </geometry>
      <material name="">
        <color rgba="0.79216 0.81961 0.93333 1"/>
      </material>
    </visual>
    <!-- <collision>
				<origin xyz="0 0 0" rpy="0 0 0" />
				<geometry>
					<mesh filename="${mesh_visual_path}/arm/link3.STL" scale="${reverse} 1 1"/>
				</geometry>
			</collision> -->
  </link>
  <joint name="arm_left_joint3" type="revolute">
    <origin rpy="-1.5708 0 0" xyz="0 0 0"/>
    <parent link="arm_left_link2"/>
    <child link="arm_left_link3"/>
    <axis xyz="0 0 -1"/>
    <limit effort="45.0" lower="-2.9670597283903604" upper="-0.17453292519943295" velocity="3.490658503988659"/>
  </joint>
  <link name="arm_left_link4">
    <inertial>
      <origin rpy="0 0 0" xyz="-1.2044E-08 0.027148 -0.0065686"/>
      <mass value="0.083265"/>
      <inertia ixx="9.7154E-05" ixy="8.5996E-12" ixz="-1.0835E-10" iyy="9.5206E-05" iyz="-6.2319E-06" izz="5.8053E-05"/>
    </inertial>
    <visual>
      <origin rpy="0 0 0" xyz="0 0 0"/>
      <geometry>
        <mesh filename="file:///home/ccs/ros2/teleop_ws/install/libertech_ranger_arm_description/share/libertech_ranger_arm_description/meshes/arm/link4.STL"/>
      </geometry>
      <material name="">
        <color rgba="0.89804 0.91765 0.92941 1"/>
      </material>
    </visual>
    <collision>
      <origin rpy="0 0 0" xyz="0 0 0"/>
      <geometry>
        <mesh filename="file:///home/ccs/ros2/teleop_ws/install/libertech_ranger_arm_description/share/libertech_ranger_arm_description/meshes/arm/link4.STL"/>
      </geometry>
    </collision>
  </link>
  <joint name="arm_left_joint4" type="revolute">
    <origin rpy="1.5708 0 0" xyz="0 0 0.27"/>
    <parent link="arm_left_link3"/>
    <child link="arm_left_link4"/>
    <axis xyz="0 0 -1"/>
    <limit effort="45.0" lower="0.0" upper="1.8325957145940461" velocity="3.490658503988659"/>
  </joint>
  <link name="arm_left_link5">
    <inertial>
      <origin rpy="0 0 0" xyz="5.7592E-05 0.0030098 0.11674"/>
      <mass value="0.10135"/>
      <inertia ixx="0.00011025" ixy="5.7106E-09" ixz="-2.863E-08" iyy="0.00013727" iyz="-1.4278E-06" izz="4.6819E-05"/>
    </inertial>
    <visual>
      <origin rpy="0 0 0" xyz="0 0 0"/>
      <geometry>
        <mesh filename="file:///home/ccs/ros2/teleop_ws/install/libertech_ranger_arm_description/share/libertech_ranger_arm_description/meshes/arm/link5.STL"/>
      </geometry>
      <material name="">
        <color rgba="0.59216 0.81961 0.93333 1"/>
      </material>
    </visual>
    <collision>
      <origin rpy="0 0 0" xyz="0 0 0"/>
      <geometry>
        <mesh filename="file:///home/ccs/ros2/teleop_ws/install/libertech_ranger_arm_description/share/libertech_ranger_arm_description/meshes/arm/link5.STL"/>
      </geometry>
    </collision>
  </link>
  <joint name="arm_left_joint5" type="revolute">
    <origin rpy="-1.5708 0 0" xyz="0 0 0"/>
    <parent link="arm_left_link4"/>
    <child link="arm_left_link5"/>
    <axis xyz="0 0 -1"/>
    <limit effort="45.0" lower="-1.5707963267948966" upper="1.5707963267948966" velocity="3.490658503988659"/>
  </joint>
  <link name="arm_left_link6">
    <inertial>
      <origin rpy="0 0 0" xyz="-0.00073065 0.035532 -0.0043423"/>
      <mass value="0.069725"/>
      <inertia ixx="3.6856E-05" ixy="-6.4441e-06" ixz="-3.2959e-06" iyy="3.961E-05" iyz="-7.8545E-06" izz="3.6658E-05"/>
    </inertial>
    <visual>
      <origin rpy="0 0 0" xyz="0 0 0"/>
      <geometry>
        <mesh filename="file:///home/ccs/ros2/teleop_ws/install/libertech_ranger_arm_description/share/libertech_ranger_arm_description/meshes/arm/link6.STL" scale="-1 1 1"/>
      </geometry>
      <material name="">
        <color rgba="0.89804 0.61765 0.92941 1"/>
      </material>
    </visual>
    <!-- <collision>
				<origin xyz="0 0 0" rpy="0 0 0" />
				<geometry>
					<mesh filename="${mesh_visual_path}/arm/link6.STL" scale="${reverse} 1 1"/>
				</geometry>
			</collision> -->
  </link>
  <joint name="arm_left_joint6" type="revolute">
    <origin rpy="1.5708 0 0" xyz="0 0 0.157"/>
    <parent link="arm_left_link5"/>
    <child link="arm_left_link6"/>
    <axis xyz="0 0 -1"/>
    <limit effort="45.0" lower="-1.3089969389957472" upper="1.3089969389957472" velocity="3.490658503988659"/>
  </joint>
  <link name="arm_left_link7">
    <inertial>
      <origin rpy="0 0 0" xyz="0.031922 0.00073671 0.0014868"/>
      <mass value="0.11565"/>
      <inertia ixx="4.2212E-05" ixy="9.2648e-09" ixz="1.6154E-06" iyy="3.1231E-05" iyz="-3.4989e-09" izz="4.1383E-05"/>
    </inertial>
    <visual>
      <origin rpy="0 0 0" xyz="0 0 0"/>
      <geometry>
        <mesh filename="file:///home/ccs/ros2/teleop_ws/install/libertech_ranger_arm_description/share/libertech_ranger_arm_description/meshes/arm/link7.STL" scale="1 -1 1"/>
      </geometry>
      <material name="">
        <color rgba="0.79216 0.81961 0.93333 1"/>
      </material>
    </visual>
    <!-- <collision>
				<origin xyz="0 0 0" rpy="0 0 0" />
				<geometry>
					<mesh filename="${mesh_visual_path}/arm/link7.STL" scale="1 ${reverse} 1" />
				</geometry>
			</collision> -->
  </link>
  <joint name="arm_left_joint7" type="revolute">
    <origin rpy="1.5708 0 1.5708" xyz="0 0.07 0"/>
    <parent link="arm_left_link6"/>
    <child link="arm_left_link7"/>
    <axis xyz="0 0 1"/>
    <limit effort="45.0" lower="-0.8726646259971648" upper="0.8726646259971648" velocity="3.490658503988659"/>
  </joint>
  <link name="arm_left_quick_release">
    <inertial>
      <origin rpy="0 0 0" xyz="-0.0046261 0.0032983 0.0069587"/>
      <mass value="0.5"/>
      <inertia ixx="3.5312E-05" ixy="-3.2715E-06" ixz="5.6547E-09" iyy="2.4468E-05" iyz="-2.9526E-09" izz="5.6973E-05"/>
    </inertial>
    <visual>
      <origin rpy="0 0 0" xyz="0 0 0"/>
      <geometry>
        <mesh filename="file:///home/ccs/ros2/teleop_ws/install/libertech_ranger_arm_description/share/libertech_ranger_arm_description/meshes/arm/quick_release.STL"/>
      </geometry>
      <material name="silver"/>
    </visual>
    <collision>
      <origin rpy="0 0 0" xyz="0 0 0"/>
      <geometry>
        <mesh filename="file:///home/ccs/ros2/teleop_ws/install/libertech_ranger_arm_description/share/libertech_ranger_arm_description/meshes/arm/quick_release.STL"/>
      </geometry>
    </collision>
  </link>
  <joint name="arm_left_quick_release_joint" type="fixed">
    <origin rpy="1.5707963267948966 3.141592653589793 1.5707963267948966" xyz="0.0675 0 0"/>
    <parent link="arm_left_link7"/>
    <child link="arm_left_quick_release"/>
    <axis xyz="0 0 0"/>
  </joint>
  <link name="arm_left_flange_link"/>
  <joint name="arm_left_flange_joint" type="fixed">
    <origin rpy="0.0 0.0 0.0 " xyz="0.0675 0 0"/>
    <parent link="arm_left_link7"/>
    <child link="arm_left_flange_link"/>
  </joint>
  <link name="arm_left_tool_link"/>
  <joint name="arm_left_tool_joint" type="fixed">
    <origin rpy="0.0 0.0 0.0 " xyz="0.15 0 0"/>
    <parent link="arm_left_flange_link"/>
    <child link="arm_left_tool_link"/>
  </joint>
  <link name="arm_left_rokubi_ft_link"/>
  <joint name="arm_left_rokubi_ft_joint" type="fixed">
    <origin rpy="0.0 1.5707963267948966 0.0 " xyz="0.0295 0 0"/>
    <parent link="arm_left_link7"/>
    <child link="arm_left_rokubi_ft_link"/>
  </joint>
  <link name="arm_left_rokubi_ft_wrench_link"/>
  <joint name="arm_left_rokubi_ft_wrench_joint" type="fixed">
    <origin rpy="0 0 0" xyz="0 0 0.032"/>
    <parent link="arm_left_rokubi_ft_link"/>
    <child link="arm_left_rokubi_ft_wrench_link"/>
  </joint>
  <joint name="arm_right_quick_release_to_gripper_right_fixed" type="fixed">
    <origin rpy="0 0 3.141592653589793" xyz="0 0 0.0015"/>
    <parent link="arm_right_quick_release"/>
    <child link="gripper_right_base"/>
  </joint>
  <link name="gripper_right_base">
    <inertial>
      <origin rpy="0 0 0" xyz="-6.29382565053791E-05 -7.99819096174029E-05 0.0512895843801642"/>
      <mass value="0.405634853674762"/>
      <inertia ixx="8.78992227335161E-05" ixy="-3.26010634033205E-07" ixz="-4.07901821655985E-08" iyy="0.000292880347487015" iyz="-5.88784289886913E-08" izz="0.000326894821287747"/>
    </inertial>
    <visual>
      <origin rpy="0 0 0" xyz="0 0 0"/>
      <geometry>
        <mesh filename="file:///home/ccs/ros2/teleop_ws/install/libertech_ranger_arm_description/share/libertech_ranger_arm_description/meshes/gripper/gripper_base.STL"/>
      </geometry>
      <material name="">
        <color rgba="0.898039215686275 0.917647058823529 0.929411764705882 1"/>
      </material>
    </visual>
    <collision>
      <origin rpy="0 0 0" xyz="0 0 0"/>
      <geometry>
        <mesh filename="file:///home/ccs/ros2/teleop_ws/install/libertech_ranger_arm_description/share/libertech_ranger_arm_description/meshes/gripper/gripper_base.STL"/>
      </geometry>
    </collision>
  </link>
  <link name="gripper_right_finger1">
    <inertial>
      <origin rpy="0 0 0" xyz="-0.000779673814706939 0.0217931787584343 -0.00555705308935257"/>
      <mass value="0.106147400593641"/>
      <inertia ixx="7.67970454667326E-05" ixy="-5.87052543036309E-07" ixz="8.02478883724728E-09" iyy="1.94631919011376E-05" iyz="4.3154611554229E-06" izz="7.53005890059645E-05"/>
    </inertial>
    <visual>
      <origin rpy="0 0 0" xyz="0 0 0"/>
      <geometry>
        <mesh filename="file:///home/ccs/ros2/teleop_ws/install/libertech_ranger_arm_description/share/libertech_ranger_arm_description/meshes/gripper/finger1.STL"/>
      </geometry>
      <material name="">
        <color rgba="1 1 1 1"/>
      </material>
    </visual>
    <collision>
      <origin rpy="0 0 0" xyz="0 0 0"/>
      <geometry>
        <mesh filename="file:///home/ccs/ros2/teleop_ws/install/libertech_ranger_arm_description/share/libertech_ranger_arm_description/meshes/gripper/finger1.STL"/>
      </geometry>
    </collision>
  </link>
  <joint name="gripper_right_joint" type="prismatic">
    <origin rpy="1.5708 0 -1.5708" xyz="-0.02 0 0.0872"/>
    <parent link="gripper_right_base"/>
    <child link="gripper_right_finger1"/>
    <axis xyz="0 0 1"/>
    <limit effort="10" lower="-0.01" upper="0.0435" velocity="2"/>
  </joint>
  <link name="gripper_right_finger2">
    <inertial>
      <origin rpy="0 0 0" xyz="-0.000779673814706977 0.0217931787584343 -0.00555705308935256"/>
      <mass value="0.106147400593641"/>
      <inertia ixx="7.67970454667326E-05" ixy="-5.87052543036278E-07" ixz="8.02478883723481E-09" iyy="1.94631919011375E-05" iyz="4.31546115542286E-06" izz="7.53005890059645E-05"/>
    </inertial>
    <visual>
      <origin rpy="0 0 0" xyz="0 0 0"/>
      <geometry>
        <mesh filename="file:///home/ccs/ros2/teleop_ws/install/libertech_ranger_arm_description/share/libertech_ranger_arm_description/meshes/gripper/finger2.STL"/>
      </geometry>
      <material name="">
        <color rgba="1 1 1 1"/>
      </material>
    </visual>
    <collision>
      <origin rpy="0 0 0" xyz="0 0 0"/>
      <geometry>
        <mesh filename="file:///home/ccs/ros2/teleop_ws/install/libertech_ranger_arm_description/share/libertech_ranger_arm_description/meshes/gripper/finger2.STL"/>
      </geometry>
    </collision>
  </link>
  <joint name="gripper_right_joint_mimic" type="prismatic">
    <origin rpy="1.5708 0 1.5708" xyz="0.02 0 0.0872"/>
    <parent link="gripper_right_base"/>
    <child link="gripper_right_finger2"/>
    <axis xyz="0 0 1"/>
    <limit effort="100" lower="-0.01" upper="0.0435" velocity="6"/>
    <!-- <mimic joint="${prefix}${gripper}_joint" multiplier="1" offset="0" /> -->
  </joint>
  <joint name="arm_left_quick_release_to_gripper_left_fixed" type="fixed">
    <origin rpy="0 0 3.141592653589793" xyz="0 0 0.0015"/>
    <parent link="arm_left_quick_release"/>
    <child link="gripper_left_base"/>
  </joint>
  <link name="gripper_left_base">
    <inertial>
      <origin rpy="0 0 0" xyz="-6.29382565053791E-05 -7.99819096174029E-05 0.0512895843801642"/>
      <mass value="0.405634853674762"/>
      <inertia ixx="8.78992227335161E-05" ixy="-3.26010634033205E-07" ixz="-4.07901821655985E-08" iyy="0.000292880347487015" iyz="-5.88784289886913E-08" izz="0.000326894821287747"/>
    </inertial>
    <visual>
      <origin rpy="0 0 0" xyz="0 0 0"/>
      <geometry>
        <mesh filename="file:///home/ccs/ros2/teleop_ws/install/libertech_ranger_arm_description/share/libertech_ranger_arm_description/meshes/gripper/gripper_base.STL"/>
      </geometry>
      <material name="">
        <color rgba="0.898039215686275 0.917647058823529 0.929411764705882 1"/>
      </material>
    </visual>
    <collision>
      <origin rpy="0 0 0" xyz="0 0 0"/>
      <geometry>
        <mesh filename="file:///home/ccs/ros2/teleop_ws/install/libertech_ranger_arm_description/share/libertech_ranger_arm_description/meshes/gripper/gripper_base.STL"/>
      </geometry>
    </collision>
  </link>
  <link name="gripper_left_finger1">
    <inertial>
      <origin rpy="0 0 0" xyz="-0.000779673814706939 0.0217931787584343 -0.00555705308935257"/>
      <mass value="0.106147400593641"/>
      <inertia ixx="7.67970454667326E-05" ixy="-5.87052543036309E-07" ixz="8.02478883724728E-09" iyy="1.94631919011376E-05" iyz="4.3154611554229E-06" izz="7.53005890059645E-05"/>
    </inertial>
    <visual>
      <origin rpy="0 0 0" xyz="0 0 0"/>
      <geometry>
        <mesh filename="file:///home/ccs/ros2/teleop_ws/install/libertech_ranger_arm_description/share/libertech_ranger_arm_description/meshes/gripper/finger1.STL"/>
      </geometry>
      <material name="">
        <color rgba="1 1 1 1"/>
      </material>
    </visual>
    <collision>
      <origin rpy="0 0 0" xyz="0 0 0"/>
      <geometry>
        <mesh filename="file:///home/ccs/ros2/teleop_ws/install/libertech_ranger_arm_description/share/libertech_ranger_arm_description/meshes/gripper/finger1.STL"/>
      </geometry>
    </collision>
  </link>
  <joint name="gripper_left_joint" type="prismatic">
    <origin rpy="1.5708 0 -1.5708" xyz="-0.02 0 0.0872"/>
    <parent link="gripper_left_base"/>
    <child link="gripper_left_finger1"/>
    <axis xyz="0 0 1"/>
    <limit effort="10" lower="-0.01" upper="0.0435" velocity="2"/>
  </joint>
  <link name="gripper_left_finger2">
    <inertial>
      <origin rpy="0 0 0" xyz="-0.000779673814706977 0.0217931787584343 -0.00555705308935256"/>
      <mass value="0.106147400593641"/>
      <inertia ixx="7.67970454667326E-05" ixy="-5.87052543036278E-07" ixz="8.02478883723481E-09" iyy="1.94631919011375E-05" iyz="4.31546115542286E-06" izz="7.53005890059645E-05"/>
    </inertial>
    <visual>
      <origin rpy="0 0 0" xyz="0 0 0"/>
      <geometry>
        <mesh filename="file:///home/ccs/ros2/teleop_ws/install/libertech_ranger_arm_description/share/libertech_ranger_arm_description/meshes/gripper/finger2.STL"/>
      </geometry>
      <material name="">
        <color rgba="1 1 1 1"/>
      </material>
    </visual>
    <collision>
      <origin rpy="0 0 0" xyz="0 0 0"/>
      <geometry>
        <mesh filename="file:///home/ccs/ros2/teleop_ws/install/libertech_ranger_arm_description/share/libertech_ranger_arm_description/meshes/gripper/finger2.STL"/>
      </geometry>
    </collision>
  </link>
  <joint name="gripper_left_joint_mimic" type="prismatic">
    <origin rpy="1.5708 0 1.5708" xyz="0.02 0 0.0872"/>
    <parent link="gripper_left_base"/>
    <child link="gripper_left_finger2"/>
    <axis xyz="0 0 1"/>
    <limit effort="100" lower="-0.01" upper="0.0435" velocity="6"/>
    <!-- <mimic joint="${prefix}${gripper}_joint" multiplier="1" offset="0" /> -->
  </joint>
  <ros2_control name="MultiInterfaceHardware" type="system">
    <hardware>
      <plugin>ign_ros2_control/IgnitionSystem</plugin>
    </hardware>
    <joint name="arm_right_joint1">
      <command_interface name="position">
        <param name="min">-1.2217304763960306</param>
        <param name="max">2.443460952792061</param>
      </command_interface>
      <command_interface name="velocity">
        <param name="min">-3.490658503988659</param>
        <param name="max">3.490658503988659</param>
      </command_interface>
      <state_interface name="position">
        <param name="initial_value">0.0</param>
      </state_interface>
      <state_interface name="velocity"/>
      <state_interface name="effort"/>
    </joint>
    <joint name="arm_right_joint2">
      <command_interface name="position">
        <param name="min">-1.5707963267948966</param>
        <param name="max">1.3962634015954636</param>
      </command_interface>
      <command_interface name="velocity">
        <param name="min">-3.490658503988659</param>
        <param name="max">3.490658503988659</param>
      </command_interface>
      <state_interface name="position">
        <param name="initial_value">0.0</param>
      </state_interface>
      <state_interface name="velocity"/>
      <state_interface name="effort"/>
    </joint>
    <joint name="arm_right_joint3">
      <command_interface name="position">
        <param name="min">-2.9670597283903604</param>
        <param name="max">-0.17453292519943295</param>
      </command_interface>
      <command_interface name="velocity">
        <param name="min">-3.490658503988659</param>
        <param name="max">3.490658503988659</param>
      </command_interface>
      <state_interface name="position">
        <param name="initial_value">0.0</param>
      </state_interface>
      <state_interface name="velocity"/>
      <state_interface name="effort"/>
    </joint>
    <joint name="arm_right_joint4">
      <command_interface name="position">
        <param name="min">0.0</param>
        <param name="max">1.8325957145940461</param>
      </command_interface>
      <command_interface name="velocity">
        <param name="min">-3.490658503988659</param>
        <param name="max">3.490658503988659</param>
      </command_interface>
      <state_interface name="position">
        <param name="initial_value">0.0</param>
      </state_interface>
      <state_interface name="velocity"/>
      <state_interface name="effort"/>
    </joint>
    <joint name="arm_right_joint5">
      <command_interface name="position">
        <param name="min">-1.5707963267948966</param>
        <param name="max">1.5707963267948966</param>
      </command_interface>
      <command_interface name="velocity">
        <param name="min">-3.490658503988659</param>
        <param name="max">3.490658503988659</param>
      </command_interface>
      <state_interface name="position">
        <param name="initial_value">0.0</param>
      </state_interface>
      <state_interface name="velocity"/>
      <state_interface name="effort"/>
    </joint>
    <joint name="arm_right_joint6">
      <command_interface name="position">
        <param name="min">-1.3089969389957472</param>
        <param name="max">1.3089969389957472</param>
      </command_interface>
      <command_interface name="velocity">
        <param name="min">-3.490658503988659</param>
        <param name="max">3.490658503988659</param>
      </command_interface>
      <state_interface name="position">
        <param name="initial_value">0.0</param>
      </state_interface>
      <state_interface name="velocity"/>
      <state_interface name="effort"/>
    </joint>
    <joint name="arm_right_joint7">
      <command_interface name="position">
        <param name="min">-0.8726646259971648</param>
        <param name="max">0.8726646259971648</param>
      </command_interface>
      <command_interface name="velocity">
        <param name="min">-3.490658503988659</param>
        <param name="max">3.490658503988659</param>
      </command_interface>
      <state_interface name="position">
        <param name="initial_value">0.0</param>
      </state_interface>
      <state_interface name="velocity"/>
      <state_interface name="effort"/>
    </joint>
    <joint name="arm_left_joint1">
      <command_interface name="position">
        <param name="min">-1.2217304763960306</param>
        <param name="max">2.443460952792061</param>
      </command_interface>
      <command_interface name="velocity">
        <param name="min">-3.490658503988659</param>
        <param name="max">3.490658503988659</param>
      </command_interface>
      <state_interface name="position">
        <param name="initial_value">0.0</param>
      </state_interface>
      <state_interface name="velocity"/>
      <state_interface name="effort"/>
    </joint>
    <joint name="arm_left_joint2">
      <command_interface name="position">
        <param name="min">-1.5707963267948966</param>
        <param name="max">1.3962634015954636</param>
      </command_interface>
      <command_interface name="velocity">
        <param name="min">-3.490658503988659</param>
        <param name="max">3.490658503988659</param>
      </command_interface>
      <state_interface name="position">
        <param name="initial_value">0.0</param>
      </state_interface>
      <state_interface name="velocity"/>
      <state_interface name="effort"/>
    </joint>
    <joint name="arm_left_joint3">
      <command_interface name="position">
        <param name="min">-2.9670597283903604</param>
        <param name="max">-0.17453292519943295</param>
      </command_interface>
      <command_interface name="velocity">
        <param name="min">-3.490658503988659</param>
        <param name="max">3.490658503988659</param>
      </command_interface>
      <state_interface name="position">
        <param name="initial_value">0.0</param>
      </state_interface>
      <state_interface name="velocity"/>
      <state_interface name="effort"/>
    </joint>
    <joint name="arm_left_joint4">
      <command_interface name="position">
        <param name="min">0.0</param>
        <param name="max">1.8325957145940461</param>
      </command_interface>
      <command_interface name="velocity">
        <param name="min">-3.490658503988659</param>
        <param name="max">3.490658503988659</param>
      </command_interface>
      <state_interface name="position">
        <param name="initial_value">0.0</param>
      </state_interface>
      <state_interface name="velocity"/>
      <state_interface name="effort"/>
    </joint>
    <joint name="arm_left_joint5">
      <command_interface name="position">
        <param name="min">-1.5707963267948966</param>
        <param name="max">1.5707963267948966</param>
      </command_interface>
      <command_interface name="velocity">
        <param name="min">-3.490658503988659</param>
        <param name="max">3.490658503988659</param>
      </command_interface>
      <state_interface name="position">
        <param name="initial_value">0.0</param>
      </state_interface>
      <state_interface name="velocity"/>
      <state_interface name="effort"/>
    </joint>
    <joint name="arm_left_joint6">
      <command_interface name="position">
        <param name="min">-1.3089969389957472</param>
        <param name="max">1.3089969389957472</param>
      </command_interface>
      <command_interface name="velocity">
        <param name="min">-3.490658503988659</param>
        <param name="max">3.490658503988659</param>
      </command_interface>
      <state_interface name="position">
        <param name="initial_value">0.0</param>
      </state_interface>
      <state_interface name="velocity"/>
      <state_interface name="effort"/>
    </joint>
    <joint name="arm_left_joint7">
      <command_interface name="position">
        <param name="min">-0.8726646259971648</param>
        <param name="max">0.8726646259971648</param>
      </command_interface>
      <command_interface name="velocity">
        <param name="min">-3.490658503988659</param>
        <param name="max">3.490658503988659</param>
      </command_interface>
      <state_interface name="position">
        <param name="initial_value">0.0</param>
      </state_interface>
      <state_interface name="velocity"/>
      <state_interface name="effort"/>
    </joint>
    <joint name="gripper_right_joint">
      <command_interface name="position">
        <param name="min">0</param>
        <param name="max">0.0425</param>
      </command_interface>
      <command_interface name="velocity">
        <param name="min">-2</param>
        <param name="max">2</param>
      </command_interface>
      <state_interface name="position">
        <param name="initial_value">0</param>
      </state_interface>
      <state_interface name="velocity"/>
      <state_interface name="effort"/>
    </joint>
    <joint name="gripper_right_joint_mimic">
      <command_interface name="position">
        <param name="min">0</param>
        <param name="max">0.0425</param>
      </command_interface>
      <command_interface name="velocity">
        <param name="min">-2</param>
        <param name="max">2</param>
      </command_interface>
      <state_interface name="position">
        <param name="initial_value">0</param>
      </state_interface>
      <state_interface name="velocity"/>
      <state_interface name="effort"/>
    </joint>
    <joint name="gripper_left_joint">
      <command_interface name="position">
        <param name="min">0</param>
        <param name="max">0.0425</param>
      </command_interface>
      <command_interface name="velocity">
        <param name="min">-2</param>
        <param name="max">2</param>
      </command_interface>
      <state_interface name="position">
        <param name="initial_value">0</param>
      </state_interface>
      <state_interface name="velocity"/>
      <state_interface name="effort"/>
    </joint>
    <joint name="gripper_left_joint_mimic">
      <command_interface name="position">
        <param name="min">0</param>
        <param name="max">0.0425</param>
      </command_interface>
      <command_interface name="velocity">
        <param name="min">-2</param>
        <param name="max">2</param>
      </command_interface>
      <state_interface name="position">
        <param name="initial_value">0</param>
      </state_interface>
      <state_interface name="velocity"/>
      <state_interface name="effort"/>
    </joint>
    <joint name="fl_wheel">
      <command_interface name="velocity">
        <param name="min">-3.14</param>
        <param name="max">3.14</param>
      </command_interface>
      <state_interface name="position">
        <param name="initial_value">0.0</param>
      </state_interface>
      <state_interface name="velocity"/>
      <state_interface name="effort"/>
    </joint>
    <joint name="fr_wheel">
      <command_interface name="velocity">
        <param name="min">-3.14</param>
        <param name="max">3.14</param>
      </command_interface>
      <state_interface name="position">
        <param name="initial_value">0.0</param>
      </state_interface>
      <state_interface name="velocity"/>
      <state_interface name="effort"/>
    </joint>
    <joint name="rl_wheel">
      <command_interface name="velocity">
        <param name="min">-3.14</param>
        <param name="max">3.14</param>
      </command_interface>
      <state_interface name="position">
        <param name="initial_value">0.0</param>
      </state_interface>
      <state_interface name="velocity"/>
      <state_interface name="effort"/>
    </joint>
    <joint name="rr_wheel">
      <command_interface name="velocity">
        <param name="min">-3.14</param>
        <param name="max">3.14</param>
      </command_interface>
      <state_interface name="position">
        <param name="initial_value">0.0</param>
      </state_interface>
      <state_interface name="velocity"/>
      <state_interface name="effort"/>
    </joint>
    <joint name="fl_steering_wheel">
      <command_interface name="position">
        <param name="min">-3.14</param>
        <param name="max">3.14</param>
      </command_interface>
      <state_interface name="position"/>
      <state_interface name="velocity"/>
      <state_interface name="effort"/>
    </joint>
    <joint name="fr_steering_wheel">
      <command_interface name="position">
        <param name="min">-3.14</param>
        <param name="max">3.14</param>
      </command_interface>
      <state_interface name="position"/>
      <state_interface name="velocity"/>
      <state_interface name="effort"/>
    </joint>
    <joint name="rl_steering_wheel">
      <command_interface name="position">
        <param name="min">-3.14</param>
        <param name="max">3.14</param>
      </command_interface>
      <state_interface name="position"/>
      <state_interface name="velocity"/>
      <state_interface name="effort"/>
    </joint>
    <joint name="rr_steering_wheel">
      <command_interface name="position">
        <param name="min">-3.14</param>
        <param name="max">3.14</param>
      </command_interface>
      <state_interface name="position"/>
      <state_interface name="velocity"/>
      <state_interface name="effort"/>
    </joint>
  </ros2_control>
  <gazebo>
    <self_collide>false</self_collide>
    <plugin filename="libign_ros2_control-system.so" name="ign_ros2_control::IgnitionROS2ControlPlugin">
      <parameters>/home/ccs/ros2/teleop_ws/install/libertech_ranger_arm_description/share/libertech_ranger_arm_description/config/ros2_controllers.yaml</parameters>
      <controller_manager_node_name>/controller_manager</controller_manager_node_name>
    </plugin>
    <plugin filename="libignition-gazebo-sensors-system.so" name="ignition::gazebo::systems::Sensors">
      <render_engine>ogre2</render_engine>
    </plugin>
    <plugin filename="ignition-gazebo-forcetorque-system" name="ignition::gazebo::systems::ForceTorque">
      </plugin>
    <plugin filename="libignition-gazebo-imu-system.so" name="ignition::gazebo::systems::Imu">
      </plugin>
    <plugin filename="ignition-gazebo-odometry-publisher-system" name="ignition::gazebo::systems::OdometryPublisher">
      <odom_publish_frequency>50</odom_publish_frequency>
      <odom_topic>/odom</odom_topic>
      <odom_frame>odom</odom_frame>
      <dimensions>2</dimensions>
      <robot_base_frame>base_footprint</robot_base_frame>
      <tf_topic>/odom/tf</tf_topic>
    </plugin>
  </gazebo>
</robot>
