<?xml version="1.0"?>

<robot name="ranger_mini_v2"  xmlns:xacro="http://ros.org/wiki/xacro">

    <!-- Base link -->
    <link name="base_link">
        <inertial>
            <origin xyz="0.0 0.0 0.0"/>
            <mass value="10"/>
            <inertia ixx="1" ixy="0.0" ixz="0.0" iyy="1" iyz="0.0" izz="1"/>
        </inertial>
        <visual>
            <origin xyz="0 0 0" rpy="1.57 0 3.14 " />
            <geometry>
                <mesh filename="file://$(find libertech_ranger_arm_description)/meshes/ranger_mini_v2/ranger_base.dae" />
            </geometry>
        </visual>
        <collision>
            <origin xyz="0 0 -0.1" rpy="0 0 0" />
            <geometry>
                <box size="0.5 0.35 0.2"/>
            </geometry>
        </collision>
 
    </link>

   <link name="fl_steering_wheel_link">
        <inertial>
            <origin xyz="0.0 0.0 0.0"/>
            <mass value="1"/>
            <inertia ixx="0.01" ixy="0.0" ixz="0.0" iyy="0.01" iyz="0.0" izz="0.01"/>
        </inertial>
        <visual>
            <origin xyz="-0.23 -0.194 0.1" rpy="1.57 0 3.14 " />
            <geometry>
                    <mesh filename="file://$(find libertech_ranger_arm_description)/meshes/ranger_mini_v2/fl.dae" />
            </geometry>
        </visual>
        <collision>
            <origin xyz="0 0 0.008" rpy="0 0 0" />
            <geometry>
                <cylinder radius="0.001" length="0.001"/>
            </geometry>
        </collision>
        <collision>
            <origin xyz="0 0 0" rpy="0 0 0" />
            <geometry>
                <cylinder radius="0.001" length="0.001"/>
            </geometry>
        </collision>
    </link>
    <joint name="fl_steering_wheel" type="revolute">
        <origin xyz="0.23 0.206 -0.1" rpy="0 0 0" />
        <parent link="base_link"/>
        <child link="fl_steering_wheel_link"/>
        <axis xyz="0 0 1" rpy="0 0 0" />
        <limit effort="5" velocity="6.28"  lower="-2.1" upper="2.1" />
    </joint>

        <link name="fl_wheel_link">
            <inertial>
                <mass value="8" />
                <origin xyz="0 0 0" />
                <inertia ixx="0.1171" ixy="0" ixz="0" iyy="0.1361" iyz="0" izz="0.1171" />
            </inertial>
            <visual>
                <origin xyz="0 0 0" rpy="1.57 0 0" />
                <geometry>
                    <cylinder length="0.01" radius="0.01" />
                </geometry>
            </visual>
            <collision>
                <origin xyz="0 0 0" rpy="1.57 0 0" />
                <geometry>
                    <cylinder length="0.08" radius="0.08" />
                </geometry>
                     <contact>
                         <ode>
                        <min_depth>0.001</min_depth>
                         </ode>
                    </contact>
            </collision>
        </link>

        <joint name="fl_wheel" type="continuous">
            <origin xyz="0.03 0.01 -0.12" rpy="0 0 0" />
            <parent link="fl_steering_wheel_link"/>
            <child link="fl_wheel_link"/>
            <axis xyz="0 1 0" rpy="0 0 0" />
        </joint>


   <link name="fr_steering_wheel_link">
        <inertial>
            <origin xyz="0.0 0.0 0.0" rpy="0.0 0.0 0.0"/>
            <mass value="1"/>
            <inertia ixx="0.01" ixy="0.0" ixz="0.0" iyy="0.01" iyz="0.0" izz="0.01"/>
        </inertial>
        <visual>
            <origin xyz="-0.23 0.194 0.1" rpy="1.57 0 3.14 " />
            <geometry>
                <mesh filename="file://$(find libertech_ranger_arm_description)/meshes/ranger_mini_v2/fr.dae" />
            </geometry>
        </visual>
        <collision>
            <origin xyz="0 0 0.008" rpy="0 0 0" />
            <geometry>
                <cylinder radius="0.001" length="0.001"/>
            </geometry>
        </collision>
    </link>
    <joint name="fr_steering_wheel" type="revolute">
        <origin xyz="0.23 -0.206 -0.1" rpy="0 0 0" />
        <parent link="base_link"/>
        <child link="fr_steering_wheel_link"/>
        <axis xyz="0 0 1" rpy="0 0 0" />
        <limit effort="5" velocity="6.28"  lower="-2.1" upper="2.1" />
    </joint>

        <link name="fr_wheel_link">
            <inertial>
                <mass value="8" />
                <origin xyz="0 0 0" />
                <inertia ixx="0.1171" ixy="0" ixz="0" iyy="0.1361" iyz="0" izz="0.1171" />
            </inertial>
            <visual>
                <origin xyz="0 0 0" rpy="1.57 0 0" />
                <geometry>
                    <cylinder length="0.01" radius="0.01" />
                </geometry>
            </visual>
            <collision>
                <origin xyz="0 0 0" rpy="1.57 0 0" />
                <geometry>
                    <cylinder length="0.08" radius="0.085" />
                </geometry>
                     <contact>
                         <ode>
                        <min_depth>0.001</min_depth>
                         </ode>
                    </contact>
            </collision>
        </link>

        <joint name="fr_wheel" type="continuous">
            <origin xyz="0.0 0.0 -0.12" rpy="0 0 0" />
            <parent link="fr_steering_wheel_link"/>
            <child link="fr_wheel_link"/>
            <axis xyz="0 1 0" rpy="0 0 0" />
        </joint>


   <link name="rl_steering_wheel_link">
        <inertial>
            <origin xyz="0.0 0.0 0.0" rpy="0.0 0.0 0.0"/>
            <mass value="1"/>
            <inertia ixx="0.01" ixy="0.0" ixz="0.0" iyy="0.01" iyz="0.0" izz="0.01"/>
        </inertial>
        <visual>
            <origin xyz="-0.23 -0.194 0.1" rpy="1.57 0 3.14 " />
            <geometry>
                    <mesh filename="file://$(find libertech_ranger_arm_description)/meshes/ranger_mini_v2/fl.dae" />
            </geometry>
        </visual>
        <collision>
            <origin xyz="0 0 0.008" rpy="0 0 0" />
            <geometry>
                <cylinder radius="0.001" length="0.001"/>
            </geometry>
        </collision>
    </link>
    <joint name="rl_steering_wheel" type="revolute">
        <origin xyz="-0.23 0.206 -0.1" rpy="0 0 0" />
        <parent link="base_link"/>
        <child link="rl_steering_wheel_link"/>
        <axis xyz="0 0 1" rpy="0 0 0" />
        <limit effort="5" velocity="6.28"  lower="-2.1" upper="2.1" />
    </joint>


        <link name="rl_wheel_link">
            <inertial>
                <mass value="8" />
                <origin xyz="0 0 0" />
                <inertia ixx="0.1171" ixy="0" ixz="0" iyy="0.1361" iyz="0" izz="0.1171" />
            </inertial>
            <visual>
                <origin xyz="0 0 0" rpy="1.57 0 0" />
                <geometry>
                    <cylinder length="0.01" radius="0.01" />
                </geometry>
            </visual>
            <collision>
                <origin xyz="0 0 0" rpy="1.57 0 0" />
                <geometry>
                    <cylinder length="0.08" radius="0.08" />
                </geometry>
                     <contact>
                         <ode>
                        <min_depth>0.001</min_depth>
                         </ode>
                    </contact>
            </collision>
        </link>

        <joint name="rl_wheel" type="continuous">
            <origin xyz="0.0 0.0 -0.12 " rpy="0 0 0" />
            <parent link="rl_steering_wheel_link"/>
            <child link="rl_wheel_link"/>
            <axis xyz="0 1 0" rpy="0 0 0" />
        </joint>


   <link name="rr_steering_wheel_link">
        <inertial>
            <origin xyz="0.0 0.0 0.0"/>
            <mass value="1"/>
            <inertia ixx="0.01" ixy="0.0" ixz="0.0" iyy="0.01" iyz="0.0" izz="0.01"/>
        </inertial>
        <visual>
            <origin xyz="-0.23 0.194 0.1" rpy="1.57 0 3.14 " />
            <geometry>
                    <mesh filename="file://$(find libertech_ranger_arm_description)/meshes/ranger_mini_v2/fr.dae" />
            </geometry>
        </visual>
        <collision>
            <origin xyz="0 0 0" rpy="0 0 0" />
            <geometry>
                <cylinder radius="0.001" length="0.001"/>
            </geometry>
        </collision>
    </link>
    <joint name="rr_steering_wheel" type="revolute">
        <origin xyz="-0.23 -0.206 -0.1" rpy="0 0 0" />
        <parent link="base_link"/>
        <child link="rr_steering_wheel_link"/>
        <axis xyz="0 0 1" rpy="0 0 0" />
        <limit effort="5" velocity="6.28"  lower="-2.1" upper="2.1" />
    </joint>

        <link name="rr_wheel_link">
            <inertial>
                <mass value="8" />
                <origin xyz="0 0 0" />
                <inertia ixx="0.1171" ixy="0" ixz="0" iyy="0.1361" iyz="0" izz="0.1171" />
            </inertial>
            <visual>
                <origin xyz="0.0 0.0 0.0" rpy="1.57 0 0" />
                <geometry>
                    <cylinder length="0.01" radius="0.01" />
                </geometry>
            </visual>
            <collision>
                <origin xyz="0 0 0" rpy="1.57 0 0" />
                <geometry>
                    <cylinder length="0.08" radius="0.08" />
                </geometry>
                     <contact>
                         <ode>
                        <min_depth>0.001</min_depth>
                         </ode>
                    </contact>
            </collision>
        </link>

        <joint name="rr_wheel" type="continuous">
            <origin xyz="0.0 0.0 -0.12 " rpy="0 0 0" />
            <parent link="rr_steering_wheel_link"/>
            <child link="rr_wheel_link"/>
            <axis xyz="0 1 0" rpy="0 0 0" />
        </joint>


    <xacro:macro name="set_gazebo_link" params="link_name">
        <gazebo reference="${link_name}">
            <collision>
                <surface>
                    <friction>
                        <ode>
                        <mu>0.2</mu>
                        <mu2>0.2</mu2>
                        </ode>
                    </friction>
                    <contact>
                        <ode>
                            <kp>100.0</kp>
                            <kd>0.1</kd>
                        </ode>
                    </contact>
                </surface>
            </collision>
        </gazebo>
    </xacro:macro>

    <xacro:set_gazebo_link link_name="fl_wheel_link"/>
    <xacro:set_gazebo_link link_name="fr_wheel_link"/>
    <xacro:set_gazebo_link link_name="rl_wheel_link"/>
    <xacro:set_gazebo_link link_name="rr_wheel_link"/>


  <ros2_control name="GazeboSystem" type="system">
    <hardware>
      <plugin>ign_ros2_control/IgnitionSystem</plugin>
    </hardware>
    
    <joint name="fl_wheel">
      <command_interface name="velocity">
        <param name="min">-3.14</param>
        <param name="max">3.14</param>
      </command_interface>
      <state_interface name="velocity"/>
      <state_interface name="effort"/>
    </joint>

    <joint name="fr_wheel">
      <command_interface name="velocity">
        <param name="min">-3.14</param>
        <param name="max">3.14</param>
      </command_interface>
      <state_interface name="velocity"/>
      <state_interface name="effort"/>
    </joint>

    <joint name="rl_wheel">
      <command_interface name="velocity">
        <param name="min">-3.14</param>
        <param name="max">3.14</param>
      </command_interface>
      <state_interface name="velocity"/>
      <state_interface name="effort"/>
    </joint>

    <joint name="rr_wheel">
      <command_interface name="velocity">
        <param name="min">-3.14</param>
        <param name="max">3.14</param>
      </command_interface>
      <state_interface name="velocity"/>
      <state_interface name="effort"/>
    </joint>

    <joint name="fl_steering_wheel">
      <command_interface name="position">
        <param name="min">-3.14</param>
        <param name="max">3.14</param>
      </command_interface>
      <state_interface name="position"/>
      <state_interface name="velocity"/>
      <state_interface name="effort"/>
    </joint>

    <joint name="fr_steering_wheel">
      <command_interface name="position">
        <param name="min">-3.14</param>
        <param name="max">3.14</param>
      </command_interface>
      <state_interface name="position"/>
      <state_interface name="velocity"/>
      <state_interface name="effort"/>
    </joint>

    <joint name="rl_steering_wheel">
      <command_interface name="position">
        <param name="min">-3.14</param>
        <param name="max">3.14</param>
      </command_interface>
      <state_interface name="position"/>
      <state_interface name="velocity"/>
      <state_interface name="effort"/>
    </joint>

    <joint name="rr_steering_wheel">
      <command_interface name="position">
        <param name="min">-3.14</param>
        <param name="max">3.14</param>
      </command_interface>
      <state_interface name="position"/>
      <state_interface name="velocity"/>
      <state_interface name="effort"/>
    </joint>
  </ros2_control> 

    <gazebo>
      <self_collide>false</self_collide>
      <plugin filename="libign_ros2_control-system.so" name="ign_ros2_control::IgnitionROS2ControlPlugin">
        <parameters>$(find libertech_ranger_arm_description)/config/ranger_mini_joint.yaml</parameters>
        <controller_manager_node_name>/controller_manager</controller_manager_node_name>
      </plugin>
    </gazebo>


</robot>
