<?xml version="1.0" ?>
<!-- =================================================================================== -->
<!-- |    This document was autogenerated by xacro from src/libertech_mobile_manipulation/libertech_ranger_arm_description/urdf/ranger_arm.xacro | -->
<!-- |    EDITING THIS FILE BY HAND IS NOT RECOMMENDED                                 | -->
<!-- =================================================================================== -->
<!--
Software License Agreement (BSD)

\file      ranger_mini_v2.urdf
\authors   Achala Athukorala <chhathuranga@gmail.com>
\copyright Copyright (c) 2024, Singapore University of Technology and Design

Redistribution and use in source and binary forms, with or without modification, are permitted provided that
the following conditions are met
 * Redistributions of source code must retain the above copyright notice, this list of conditions and the
   following disclaimer.
 * Redistributions in binary form must reproduce the above copyright notice, this list of conditions and the
   following disclaimer in the documentation and/or other materials provided with the distribution.
 * Neither the name of Clearpath Robotics nor the names of its contributors may be used to endorse or promote
   products derived from this software without specific prior written permission.

THIS SOFTWARE IS PROVIDED BY THE COPYRIGHT HOLDERS AND CONTRIBUTORS "AS IS" AND ANY EXPRESS OR IMPLIED WAR-
RANTIES, INCLUDING, BUT NOT LIMITED TO, THE IMPLIED WARRANTIES OF MERCHANTABILITY AND FITNESS FOR A PARTICULAR
PURPOSE ARE DISCLAIMED. IN NO EVENT SHALL THE COPYRIGHT HOLDER OR CONTRIBUTORS BE LIABLE FOR ANY DIRECT, IN-
DIRECT, INCIDENTAL, SPECIAL, EXEMPLARY, OR CONSEQUENTIAL DAMAGES (INCLUDING, BUT NOT LIMITED TO, PROCUREMENT
OF SUBSTITUTE GOODS OR SERVICES; LOSS OF USE, DATA, OR PROFITS; OR BUSINESS INTERRUPTION) HOWEVER CAUSED AND
ON ANY THEORY OF LIABILITY, WHETHER IN CONTRACT, STRICT LIABILITY, OR TORT (INCLUDING NEGLIGENCE OR OTHERWISE)
ARISING IN ANY WAY OUT OF THE USE OF THIS SOFTWARE, EVEN IF ADVISED OF THE POSSIBILITY OF SUCH DAMAGE.
-->
<!-- Ranger Mini V2 Mobile Base -->
<robot name="ranger_arm">
  <!-- Sensors -->
  <material name="black">
    <color rgba="0.0 0.0 0.0 1.0"/>
  </material>
  <material name="blue">
    <color rgba="0.0 0.0 0.8 1.0"/>
  </material>
  <material name="green">
    <color rgba="0.0 0.8 0.0 1.0"/>
  </material>
  <material name="grey">
    <color rgba="0.2 0.2 0.2 1.0"/>
  </material>
  <material name="grey_alpha">
    <color rgba="0.2 0.2 0.2 0.5"/>
  </material>
  <material name="silver">
    <color rgba="0.9137254901960784 0.9137254901960784 0.8470588235294118 1.0"/>
  </material>
  <material name="orange">
    <color rgba="1.0 0.4235294117647059 0.0392156862745098 1.0"/>
  </material>
  <material name="orange_alpha">
    <color rgba="1.0 0.4235294117647059 0.0392156862745098 0.85"/>
  </material>
  <material name="brown">
    <color rgba="0.8705882352941177 0.8117647058823529 0.7647058823529411 1.0"/>
  </material>
  <material name="red">
    <color rgba="0.8 0.0 0.0 1.0"/>
  </material>
  <material name="white_alpha">
    <color rgba="1.0 1.0 1.0 0.5"/>
  </material>
  <material name="white">
    <color rgba="1.0 1.0 1.0 1.0"/>
  </material>
  <link name="base_footprint"/>
  <joint name="base_link_joint" type="fixed">
    <origin xyz="0 0 0.28"/>
    <parent link="base_footprint"/>
    <child link="base_link"/>
  </joint>
  <link name="base_link">
    <inertial>
      <origin xyz="0.0 0.0 0.0"/>
      <mass value="20"/>
      <inertia ixx="1" ixy="0.0" ixz="0.0" iyy="1" iyz="0.0" izz="1"/>
    </inertial>
    <visual>
      <origin rpy="1.57 0 3.14 " xyz="0 0 0"/>
      <geometry>
        <mesh filename="file:///home/ccs/ros2/teleop_ws/install/libertech_ranger_arm_description/share/libertech_ranger_arm_description/meshes/ranger_mini_v2/ranger_base.dae"/>
      </geometry>
    </visual>
    <collision>
      <origin rpy="0 0 0" xyz="0 0 -0.1"/>
      <geometry>
        <box size="0.5 0.35 0.2"/>
      </geometry>
    </collision>
  </link>
  
  <link name="base_add_on">
    <inertial>
      <origin rpy="0 0 0" xyz="0.0455338389926168 -0.00103634765767435 0.220800927413883"/>
      <mass value="6.44138353782306"/>
      <inertia ixx="0.0992945121069776" ixy="5.84470364161191E-05" ixz="-4.71376239762533E-07" iyy="0.124094455743998" iyz="1.23371057479671E-08" izz="0.13752951719075"/>
    </inertial>
    <visual>
      <origin rpy="0 0 0" xyz="0 0 0"/>
      <geometry>
        <mesh filename="file:///home/ccs/ros2/teleop_ws/install/libertech_ranger_arm_description/share/libertech_ranger_arm_description/meshes/ranger_mini_v2/base_add_on.STL"/>
      </geometry>
      <material name="">
        <color rgba="0.792156862745098 0.819607843137255 0.933333333333333 1"/>
      </material>
    </visual>
    <collision>
      <origin rpy="0 0 0" xyz="0 0 0"/>
      <geometry>
        <mesh filename="file:///home/ccs/ros2/teleop_ws/install/libertech_ranger_arm_description/share/libertech_ranger_arm_description/meshes/ranger_mini_v2/base_add_on.STL"/>
      </geometry>
    </collision>
  </link>
  <joint name="base_joint" type="fixed">
    <origin rpy="0 0 0" xyz="0.015 0.0 0.024"/>
    <parent link="base_link"/>
    <child link="base_add_on"/>
  </joint>

  <link name="camera_link"/>
  <joint name="camera_joint" type="fixed">
    <parent link="base_add_on"/>
    <child link="camera_link"/>
    <origin rpy="0 0 0" xyz="0.34 0 0.55"/>
  </joint>
  <link name="camera_optical_frame"/>
  <joint name="camera_optical_joint" type="fixed">
    <origin rpy="-1.5707963267948966 0.0 -1.5707963267948966" xyz="0 0 0"/>
    <parent link="camera_link"/>
    <child link="camera_optical_frame"/>
  </joint>
  <link name="lidar_link"/>
  <joint name="lidar_joint" type="fixed">
    <parent link="base_add_on"/>
    <child link="lidar_link"/>
    <origin rpy="0 0 0" xyz="0.23523 0 0.6"/>
  </joint>
  
  <joint name="base_add_on_to_arm_right_fixed" type="fixed">
    <origin rpy="-1.5708 0 -3.1416" xyz="0.23523 -0.16811 0.4925"/>
    <parent link="base_add_on"/>
    <child link="arm_right_link0"/>
  </joint>
  <link name="arm_right_link0">
    <inertial>
      <origin rpy="0 0 0" xyz="0.00015789 1.1425E-05 -0.026926"/>
      <mass value="0.057424"/>
      <inertia ixx="3.4494E-05" ixy="-8.7249E-09" ixz="1.5443E-08" iyy="3.4241E-05" iyz="3.5354E-09" izz="6.5635E-05"/>
    </inertial>
    <visual>
      <origin rpy="0 0 0" xyz="0 0 0"/>
      <geometry>
        <mesh filename="file:///home/ccs/ros2/teleop_ws/install/libertech_ranger_arm_description/share/libertech_ranger_arm_description/meshes/arm/link0.STL"/>
      </geometry>
      <material name="">
        <color rgba="0.79216 0.81961 0.93333 1"/>
      </material>
    </visual>
    <collision>
      <origin rpy="0 0 0" xyz="0 0 0"/>
      <geometry>
        <mesh filename="file:///home/ccs/ros2/teleop_ws/install/libertech_ranger_arm_description/share/libertech_ranger_arm_description/meshes/arm/link0.STL"/>
      </geometry>
    </collision>
  </link>
  <link name="arm_right_link1">
    <inertial>
      <origin rpy="0 0 0" xyz="0.0067996 -8.3556E-09 0.02733"/>
      <mass value="0.10407"/>
      <inertia ixx="8.2311E-05" ixy="1.9979E-10" ixz="-1.0236E-05" iyy="0.00018185" iyz="-5.5152E-12" izz="0.00017098"/>
    </inertial>
    <visual>
      <origin rpy="0 0 0" xyz="0 0 0"/>
      <geometry>
        <mesh filename="file:///home/ccs/ros2/teleop_ws/install/libertech_ranger_arm_description/share/libertech_ranger_arm_description/meshes/arm/link1.STL"/>
      </geometry>
      <material name="">
        <color rgba="0.59804 0.91765 0.92941 1"/>
      </material>
    </visual>
    <collision>
      <origin rpy="0 0 0" xyz="0 0 0"/>
      <geometry>
        <mesh filename="file:///home/ccs/ros2/teleop_ws/install/libertech_ranger_arm_description/share/libertech_ranger_arm_description/meshes/arm/link1.STL"/>
      </geometry>
    </collision>
  </link>
  <joint name="arm_right_joint1" type="revolute">
    <origin rpy="0 0 0" xyz="0 0 0"/>
    <parent link="arm_right_link0"/>
    <child link="arm_right_link1"/>
    <axis xyz="0 0 1"/>
    <limit effort="45.0" lower="-2.0943951023931953" upper="2.0943951023931953" velocity="20.943951023931955"/>
  </joint>
  <link name="arm_right_link2">
    <inertial>
      <origin rpy="0 0 0" xyz="-0.00010195 0.083732 -0.00067262"/>
      <mass value="0.23039"/>
      <inertia ixx="0.00041883" ixy="-5.1421E-08" ixz="7.7215E-09" iyy="0.00018974" iyz="6.3393E-06" izz="0.00050303"/>
    </inertial>
    <visual>
      <origin rpy="0 0 0" xyz="0 0 0"/>
      <geometry>
        <mesh filename="file:///home/ccs/ros2/teleop_ws/install/libertech_ranger_arm_description/share/libertech_ranger_arm_description/meshes/arm/link2.STL"/>
      </geometry>
      <material name="">
        <color rgba="0.79216 0.81961 0.93333 1"/>
      </material>
    </visual>
    <collision>
      <origin rpy="0 0 0" xyz="0 0 0"/>
      <geometry>
        <mesh filename="file:///home/ccs/ros2/teleop_ws/install/libertech_ranger_arm_description/share/libertech_ranger_arm_description/meshes/arm/link2.STL"/>
      </geometry>
    </collision>
  </link>
  <joint name="arm_right_joint2" type="revolute">
    <origin rpy="1.5708 0 1.5708" xyz="0 0 0.062"/>
    <parent link="arm_right_link1"/>
    <child link="arm_right_link2"/>
    <axis xyz="0 0 1"/>
    <limit effort="45.0" lower="-1.5707963267948966" upper="1.0471975511965976" velocity="20.943951023931955"/>
  </joint>
  <link name="arm_right_link3">
    <inertial>
      <origin rpy="0 0 0" xyz="0.0058456 -0.0011149 0.26476"/>
      <mass value="0.098445"/>
      <inertia ixx="7.7802E-05" ixy="1.0294e-06" ixz="-1.0177e-05" iyy="0.00011471" iyz="1.6629E-07" izz="6.9147E-05"/>
    </inertial>
    <visual>
      <origin rpy="0 0 0" xyz="0 0 0"/>
      <geometry>
        <mesh filename="file:///home/ccs/ros2/teleop_ws/install/libertech_ranger_arm_description/share/libertech_ranger_arm_description/meshes/arm/link3.STL" scale="1 1 1"/>
      </geometry>
      <material name="">
        <color rgba="0.79216 0.81961 0.93333 1"/>
      </material>
    </visual>
    <!-- <collision>
				<origin xyz="0 0 0" rpy="0 0 0" />
				<geometry>
					<mesh filename="${mesh_visual_path}/arm/link3.STL" scale="${reverse} 1 1"/>
				</geometry>
			</collision> -->
  </link>
  <joint name="arm_right_joint3" type="revolute">
    <origin rpy="-1.5708 0 0" xyz="0 0 0"/>
    <parent link="arm_right_link2"/>
    <child link="arm_right_link3"/>
    <axis xyz="0 0 1"/>
    <limit effort="45.0" lower="-2.0943951023931953" upper="2.0943951023931953" velocity="20.943951023931955"/>
  </joint>
  <link name="arm_right_link4">
    <inertial>
      <origin rpy="0 0 0" xyz="-1.2044E-08 0.027148 -0.0065686"/>
      <mass value="0.083265"/>
      <inertia ixx="9.7154E-05" ixy="8.5996E-12" ixz="-1.0835E-10" iyy="9.5206E-05" iyz="-6.2319E-06" izz="5.8053E-05"/>
    </inertial>
    <visual>
      <origin rpy="0 0 0" xyz="0 0 0"/>
      <geometry>
        <mesh filename="file:///home/ccs/ros2/teleop_ws/install/libertech_ranger_arm_description/share/libertech_ranger_arm_description/meshes/arm/link4.STL"/>
      </geometry>
      <material name="">
        <color rgba="0.89804 0.91765 0.92941 1"/>
      </material>
    </visual>
    <collision>
      <origin rpy="0 0 0" xyz="0 0 0"/>
      <geometry>
        <mesh filename="file:///home/ccs/ros2/teleop_ws/install/libertech_ranger_arm_description/share/libertech_ranger_arm_description/meshes/arm/link4.STL"/>
      </geometry>
    </collision>
  </link>
  <joint name="arm_right_joint4" type="revolute">
    <origin rpy="1.5708 0 0" xyz="0 0 0.27"/>
    <parent link="arm_right_link3"/>
    <child link="arm_right_link4"/>
    <axis xyz="0 0 1"/>
    <limit effort="45.0" lower="0.0" upper="1.7453292519943295" velocity="20.943951023931955"/>
  </joint>
  <link name="arm_right_link5">
    <inertial>
      <origin rpy="0 0 0" xyz="5.7592E-05 0.0030098 0.11674"/>
      <mass value="0.10135"/>
      <inertia ixx="0.00011025" ixy="5.7106E-09" ixz="-2.863E-08" iyy="0.00013727" iyz="-1.4278E-06" izz="4.6819E-05"/>
    </inertial>
    <visual>
      <origin rpy="0 0 0" xyz="0 0 0"/>
      <geometry>
        <mesh filename="file:///home/ccs/ros2/teleop_ws/install/libertech_ranger_arm_description/share/libertech_ranger_arm_description/meshes/arm/link5.STL"/>
      </geometry>
      <material name="">
        <color rgba="0.59216 0.81961 0.93333 1"/>
      </material>
    </visual>
    <collision>
      <origin rpy="0 0 0" xyz="0 0 0"/>
      <geometry>
        <mesh filename="file:///home/ccs/ros2/teleop_ws/install/libertech_ranger_arm_description/share/libertech_ranger_arm_description/meshes/arm/link5.STL"/>
      </geometry>
    </collision>
  </link>
  <joint name="arm_right_joint5" type="revolute">
    <origin rpy="-1.5708 0 0" xyz="0 0 0"/>
    <parent link="arm_right_link4"/>
    <child link="arm_right_link5"/>
    <axis xyz="0 0 1"/>
    <limit effort="45.0" lower="-2.0943951023931953" upper="2.0943951023931953" velocity="20.943951023931955"/>
  </joint>
  <link name="arm_right_link6">
    <inertial>
      <origin rpy="0 0 0" xyz="-0.00073065 0.035532 -0.0043423"/>
      <mass value="0.069725"/>
      <inertia ixx="3.6856E-05" ixy="6.4441e-06" ixz="3.2959e-06" iyy="3.961E-05" iyz="-7.8545E-06" izz="3.6658E-05"/>
    </inertial>
    <visual>
      <origin rpy="0 0 0" xyz="0 0 0"/>
      <geometry>
        <mesh filename="file:///home/ccs/ros2/teleop_ws/install/libertech_ranger_arm_description/share/libertech_ranger_arm_description/meshes/arm/link6.STL" scale="1 1 1"/>
      </geometry>
      <material name="">
        <color rgba="0.89804 0.61765 0.92941 1"/>
      </material>
    </visual>
    <!-- <collision>
				<origin xyz="0 0 0" rpy="0 0 0" />
				<geometry>
					<mesh filename="${mesh_visual_path}/arm/link6.STL" scale="${reverse} 1 1"/>
				</geometry>
			</collision> -->
  </link>
  <joint name="arm_right_joint6" type="revolute">
    <origin rpy="1.5708 0 0" xyz="0 0 0.157"/>
    <parent link="arm_right_link5"/>
    <child link="arm_right_link6"/>
    <axis xyz="0 0 1"/>
    <limit effort="45.0" lower="-0.9599310885968813" upper="0.9599310885968813" velocity="20.943951023931955"/>
  </joint>
  <link name="arm_right_link7">
    <inertial>
      <origin rpy="0 0 0" xyz="0.031922 0.00073671 0.0014868"/>
      <mass value="0.11565"/>
      <inertia ixx="4.2212E-05" ixy="-9.2648e-09" ixz="1.6154E-06" iyy="3.1231E-05" iyz="3.4989e-09" izz="4.1383E-05"/>
    </inertial>
    <visual>
      <origin rpy="0 0 0" xyz="0 0 0"/>
      <geometry>
        <mesh filename="file:///home/ccs/ros2/teleop_ws/install/libertech_ranger_arm_description/share/libertech_ranger_arm_description/meshes/arm/link7.STL" scale="1 1 1"/>
      </geometry>
      <material name="">
        <color rgba="0.79216 0.81961 0.93333 1"/>
      </material>
    </visual>
    <!-- <collision>
				<origin xyz="0 0 0" rpy="0 0 0" />
				<geometry>
					<mesh filename="${mesh_visual_path}/arm/link7.STL" scale="1 ${reverse} 1" />
				</geometry>
			</collision> -->
  </link>
  <joint name="arm_right_joint7" type="revolute">
    <origin rpy="-1.5708 0 1.5708" xyz="0 0.07 0"/>
    <parent link="arm_right_link6"/>
    <child link="arm_right_link7"/>
    <axis xyz="0 0 -1"/>
    <limit effort="45.0" lower="-1.3089969389957472" upper="1.3089969389957472" velocity="6.28"/>
  </joint>
  <link name="arm_right_quick_release">
    <inertial>
      <origin rpy="0 0 0" xyz="-0.0046261 0.0032983 0.0069587"/>
      <mass value="0.5"/>
      <inertia ixx="3.5312E-05" ixy="-3.2715E-06" ixz="5.6547E-09" iyy="2.4468E-05" iyz="-2.9526E-09" izz="5.6973E-05"/>
    </inertial>
    <visual>
      <origin rpy="0 0 0" xyz="0 0 0"/>
      <geometry>
        <mesh filename="file:///home/ccs/ros2/teleop_ws/install/libertech_ranger_arm_description/share/libertech_ranger_arm_description/meshes/arm/quick_release.STL"/>
      </geometry>
      <material name="silver"/>
    </visual>
    <collision>
      <origin rpy="0 0 0" xyz="0 0 0"/>
      <geometry>
        <mesh filename="file:///home/ccs/ros2/teleop_ws/install/libertech_ranger_arm_description/share/libertech_ranger_arm_description/meshes/arm/quick_release.STL"/>
      </geometry>
    </collision>
  </link>
  <joint name="arm_right_quick_release_joint" type="fixed">
    <origin rpy="1.5707963267948966 3.141592653589793 1.5707963267948966" xyz="0.0675 0 0"/>
    <parent link="arm_right_link7"/>
    <child link="arm_right_quick_release"/>
    <axis xyz="0 0 0"/>
  </joint>
  <link name="arm_right_flange_link"/>
  <joint name="arm_right_flange_joint" type="fixed">
    <origin rpy="0.0 0.0 0.0 " xyz="0.0675 0 0"/>
    <parent link="arm_right_link7"/>
    <child link="arm_right_flange_link"/>
  </joint>
  <link name="arm_right_rokubi_ft_link"/>
  <joint name="arm_right_rokubi_ft_joint" type="fixed">
    <origin rpy="3.141592653589793 -1.5707963267948966 0.0 " xyz="0.0295 0 0"/>
    <parent link="arm_right_link7"/>
    <child link="arm_right_rokubi_ft_link"/>
  </joint>
  <link name="arm_right_rokubi_ft_wrench_link"/>
  <joint name="arm_right_rokubi_ft_wrench_joint" type="fixed">
    <origin rpy="0 0 0" xyz="0 0 0.032"/>
    <parent link="arm_right_rokubi_ft_link"/>
    <child link="arm_right_rokubi_ft_wrench_link"/>
  </joint>
  <joint name="base_add_on_to_arm_left_fixed" type="fixed">
    <origin rpy="1.5708 0 -3.1416" xyz="0.23523 0.16811 0.4925"/>
    <parent link="base_add_on"/>
    <child link="arm_left_link0"/>
  </joint>
  <link name="arm_left_link0">
    <inertial>
      <origin rpy="0 0 0" xyz="0.00015789 1.1425E-05 -0.026926"/>
      <mass value="0.057424"/>
      <inertia ixx="3.4494E-05" ixy="-8.7249E-09" ixz="1.5443E-08" iyy="3.4241E-05" iyz="3.5354E-09" izz="6.5635E-05"/>
    </inertial>
    <visual>
      <origin rpy="0 0 0" xyz="0 0 0"/>
      <geometry>
        <mesh filename="file:///home/ccs/ros2/teleop_ws/install/libertech_ranger_arm_description/share/libertech_ranger_arm_description/meshes/arm/link0.STL"/>
      </geometry>
      <material name="">
        <color rgba="0.79216 0.81961 0.93333 1"/>
      </material>
    </visual>
    <collision>
      <origin rpy="0 0 0" xyz="0 0 0"/>
      <geometry>
        <mesh filename="file:///home/ccs/ros2/teleop_ws/install/libertech_ranger_arm_description/share/libertech_ranger_arm_description/meshes/arm/link0.STL"/>
      </geometry>
    </collision>
  </link>
  <link name="arm_left_link1">
    <inertial>
      <origin rpy="0 0 0" xyz="0.0067996 -8.3556E-09 0.02733"/>
      <mass value="0.10407"/>
      <inertia ixx="8.2311E-05" ixy="1.9979E-10" ixz="-1.0236E-05" iyy="0.00018185" iyz="-5.5152E-12" izz="0.00017098"/>
    </inertial>
    <visual>
      <origin rpy="0 0 0" xyz="0 0 0"/>
      <geometry>
        <mesh filename="file:///home/ccs/ros2/teleop_ws/install/libertech_ranger_arm_description/share/libertech_ranger_arm_description/meshes/arm/link1.STL"/>
      </geometry>
      <material name="">
        <color rgba="0.59804 0.91765 0.92941 1"/>
      </material>
    </visual>
    <collision>
      <origin rpy="0 0 0" xyz="0 0 0"/>
      <geometry>
        <mesh filename="file:///home/ccs/ros2/teleop_ws/install/libertech_ranger_arm_description/share/libertech_ranger_arm_description/meshes/arm/link1.STL"/>
      </geometry>
    </collision>
  </link>
  <joint name="arm_left_joint1" type="revolute">
    <origin rpy="0 0 0" xyz="0 0 0"/>
    <parent link="arm_left_link0"/>
    <child link="arm_left_link1"/>
    <axis xyz="0 0 -1"/>
    <limit effort="45.0" lower="-2.0943951023931953" upper="2.0943951023931953" velocity="20.943951023931955"/>
  </joint>
  <link name="arm_left_link2">
    <inertial>
      <origin rpy="0 0 0" xyz="-0.00010195 0.083732 -0.00067262"/>
      <mass value="0.23039"/>
      <inertia ixx="0.00041883" ixy="-5.1421E-08" ixz="7.7215E-09" iyy="0.00018974" iyz="6.3393E-06" izz="0.00050303"/>
    </inertial>
    <visual>
      <origin rpy="0 0 0" xyz="0 0 0"/>
      <geometry>
        <mesh filename="file:///home/ccs/ros2/teleop_ws/install/libertech_ranger_arm_description/share/libertech_ranger_arm_description/meshes/arm/link2.STL"/>
      </geometry>
      <material name="">
        <color rgba="0.79216 0.81961 0.93333 1"/>
      </material>
    </visual>
    <collision>
      <origin rpy="0 0 0" xyz="0 0 0"/>
      <geometry>
        <mesh filename="file:///home/ccs/ros2/teleop_ws/install/libertech_ranger_arm_description/share/libertech_ranger_arm_description/meshes/arm/link2.STL"/>
      </geometry>
    </collision>
  </link>
  <joint name="arm_left_joint2" type="revolute">
    <origin rpy="1.5708 0 1.5708" xyz="0 0 0.062"/>
    <parent link="arm_left_link1"/>
    <child link="arm_left_link2"/>
    <axis xyz="0 0 -1"/>
    <limit effort="45.0" lower="-1.5707963267948966" upper="1.0471975511965976" velocity="20.943951023931955"/>
  </joint>
  <link name="arm_left_link3">
    <inertial>
      <origin rpy="0 0 0" xyz="0.0058456 -0.0011149 0.26476"/>
      <mass value="0.098445"/>
      <inertia ixx="7.7802E-05" ixy="-1.0294e-06" ixz="1.0177e-05" iyy="0.00011471" iyz="1.6629E-07" izz="6.9147E-05"/>
    </inertial>
    <visual>
      <origin rpy="0 0 0" xyz="0 0 0"/>
      <geometry>
        <mesh filename="file:///home/ccs/ros2/teleop_ws/install/libertech_ranger_arm_description/share/libertech_ranger_arm_description/meshes/arm/link3.STL" scale="-1 1 1"/>
      </geometry>
      <material name="">
        <color rgba="0.79216 0.81961 0.93333 1"/>
      </material>
    </visual>
    <!-- <collision>
				<origin xyz="0 0 0" rpy="0 0 0" />
				<geometry>
					<mesh filename="${mesh_visual_path}/arm/link3.STL" scale="${reverse} 1 1"/>
				</geometry>
			</collision> -->
  </link>
  <joint name="arm_left_joint3" type="revolute">
    <origin rpy="-1.5708 0 0" xyz="0 0 0"/>
    <parent link="arm_left_link2"/>
    <child link="arm_left_link3"/>
    <axis xyz="0 0 -1"/>
    <limit effort="45.0" lower="-2.0943951023931953" upper="2.0943951023931953" velocity="20.943951023931955"/>
  </joint>
  <link name="arm_left_link4">
    <inertial>
      <origin rpy="0 0 0" xyz="-1.2044E-08 0.027148 -0.0065686"/>
      <mass value="0.083265"/>
      <inertia ixx="9.7154E-05" ixy="8.5996E-12" ixz="-1.0835E-10" iyy="9.5206E-05" iyz="-6.2319E-06" izz="5.8053E-05"/>
    </inertial>
    <visual>
      <origin rpy="0 0 0" xyz="0 0 0"/>
      <geometry>
        <mesh filename="file:///home/ccs/ros2/teleop_ws/install/libertech_ranger_arm_description/share/libertech_ranger_arm_description/meshes/arm/link4.STL"/>
      </geometry>
      <material name="">
        <color rgba="0.89804 0.91765 0.92941 1"/>
      </material>
    </visual>
    <collision>
      <origin rpy="0 0 0" xyz="0 0 0"/>
      <geometry>
        <mesh filename="file:///home/ccs/ros2/teleop_ws/install/libertech_ranger_arm_description/share/libertech_ranger_arm_description/meshes/arm/link4.STL"/>
      </geometry>
    </collision>
  </link>
  <joint name="arm_left_joint4" type="revolute">
    <origin rpy="1.5708 0 0" xyz="0 0 0.27"/>
    <parent link="arm_left_link3"/>
    <child link="arm_left_link4"/>
    <axis xyz="0 0 -1"/>
    <limit effort="45.0" lower="0.0" upper="1.7453292519943295" velocity="20.943951023931955"/>
  </joint>
  <link name="arm_left_link5">
    <inertial>
      <origin rpy="0 0 0" xyz="5.7592E-05 0.0030098 0.11674"/>
      <mass value="0.10135"/>
      <inertia ixx="0.00011025" ixy="5.7106E-09" ixz="-2.863E-08" iyy="0.00013727" iyz="-1.4278E-06" izz="4.6819E-05"/>
    </inertial>
    <visual>
      <origin rpy="0 0 0" xyz="0 0 0"/>
      <geometry>
        <mesh filename="file:///home/ccs/ros2/teleop_ws/install/libertech_ranger_arm_description/share/libertech_ranger_arm_description/meshes/arm/link5.STL"/>
      </geometry>
      <material name="">
        <color rgba="0.59216 0.81961 0.93333 1"/>
      </material>
    </visual>
    <collision>
      <origin rpy="0 0 0" xyz="0 0 0"/>
      <geometry>
        <mesh filename="file:///home/ccs/ros2/teleop_ws/install/libertech_ranger_arm_description/share/libertech_ranger_arm_description/meshes/arm/link5.STL"/>
      </geometry>
    </collision>
  </link>
  <joint name="arm_left_joint5" type="revolute">
    <origin rpy="-1.5708 0 0" xyz="0 0 0"/>
    <parent link="arm_left_link4"/>
    <child link="arm_left_link5"/>
    <axis xyz="0 0 -1"/>
    <limit effort="45.0" lower="-2.0943951023931953" upper="2.0943951023931953" velocity="20.943951023931955"/>
  </joint>
  <link name="arm_left_link6">
    <inertial>
      <origin rpy="0 0 0" xyz="-0.00073065 0.035532 -0.0043423"/>
      <mass value="0.069725"/>
      <inertia ixx="3.6856E-05" ixy="-6.4441e-06" ixz="-3.2959e-06" iyy="3.961E-05" iyz="-7.8545E-06" izz="3.6658E-05"/>
    </inertial>
    <visual>
      <origin rpy="0 0 0" xyz="0 0 0"/>
      <geometry>
        <mesh filename="file:///home/ccs/ros2/teleop_ws/install/libertech_ranger_arm_description/share/libertech_ranger_arm_description/meshes/arm/link6.STL" scale="-1 1 1"/>
      </geometry>
      <material name="">
        <color rgba="0.89804 0.61765 0.92941 1"/>
      </material>
    </visual>
    <!-- <collision>
				<origin xyz="0 0 0" rpy="0 0 0" />
				<geometry>
					<mesh filename="${mesh_visual_path}/arm/link6.STL" scale="${reverse} 1 1"/>
				</geometry>
			</collision> -->
  </link>
  <joint name="arm_left_joint6" type="revolute">
    <origin rpy="1.5708 0 0" xyz="0 0 0.157"/>
    <parent link="arm_left_link5"/>
    <child link="arm_left_link6"/>
    <axis xyz="0 0 -1"/>
    <limit effort="45.0" lower="-0.9599310885968813" upper="0.9599310885968813" velocity="20.943951023931955"/>
  </joint>
  <link name="arm_left_link7">
    <inertial>
      <origin rpy="0 0 0" xyz="0.031922 0.00073671 0.0014868"/>
      <mass value="0.11565"/>
      <inertia ixx="4.2212E-05" ixy="9.2648e-09" ixz="1.6154E-06" iyy="3.1231E-05" iyz="-3.4989e-09" izz="4.1383E-05"/>
    </inertial>
    <visual>
      <origin rpy="0 0 0" xyz="0 0 0"/>
      <geometry>
        <mesh filename="file:///home/ccs/ros2/teleop_ws/install/libertech_ranger_arm_description/share/libertech_ranger_arm_description/meshes/arm/link7.STL" scale="1 -1 1"/>
      </geometry>
      <material name="">
        <color rgba="0.79216 0.81961 0.93333 1"/>
      </material>
    </visual>
    <!-- <collision>
				<origin xyz="0 0 0" rpy="0 0 0" />
				<geometry>
					<mesh filename="${mesh_visual_path}/arm/link7.STL" scale="1 ${reverse} 1" />
				</geometry>
			</collision> -->
  </link>
  <joint name="arm_left_joint7" type="revolute">
    <origin rpy="1.5708 0 1.5708" xyz="0 0.07 0"/>
    <parent link="arm_left_link6"/>
    <child link="arm_left_link7"/>
    <axis xyz="0 0 1"/>
    <limit effort="45.0" lower="-1.3089969389957472" upper="1.3089969389957472" velocity="6.28"/>
  </joint>
  <link name="arm_left_quick_release">
    <inertial>
      <origin rpy="0 0 0" xyz="-0.0046261 0.0032983 0.0069587"/>
      <mass value="0.5"/>
      <inertia ixx="3.5312E-05" ixy="-3.2715E-06" ixz="5.6547E-09" iyy="2.4468E-05" iyz="-2.9526E-09" izz="5.6973E-05"/>
    </inertial>
    <visual>
      <origin rpy="0 0 0" xyz="0 0 0"/>
      <geometry>
        <mesh filename="file:///home/ccs/ros2/teleop_ws/install/libertech_ranger_arm_description/share/libertech_ranger_arm_description/meshes/arm/quick_release.STL"/>
      </geometry>
      <material name="silver"/>
    </visual>
    <collision>
      <origin rpy="0 0 0" xyz="0 0 0"/>
      <geometry>
        <mesh filename="file:///home/ccs/ros2/teleop_ws/install/libertech_ranger_arm_description/share/libertech_ranger_arm_description/meshes/arm/quick_release.STL"/>
      </geometry>
    </collision>
  </link>
  <joint name="arm_left_quick_release_joint" type="fixed">
    <origin rpy="1.5707963267948966 3.141592653589793 1.5707963267948966" xyz="0.0675 0 0"/>
    <parent link="arm_left_link7"/>
    <child link="arm_left_quick_release"/>
    <axis xyz="0 0 0"/>
  </joint>
  <link name="arm_left_flange_link"/>
  <joint name="arm_left_flange_joint" type="fixed">
    <origin rpy="0.0 0.0 0.0 " xyz="0.0675 0 0"/>
    <parent link="arm_left_link7"/>
    <child link="arm_left_flange_link"/>
  </joint>
  <link name="arm_left_rokubi_ft_link"/>
  <joint name="arm_left_rokubi_ft_joint" type="fixed">
    <origin rpy="0.0 1.5707963267948966 0.0 " xyz="0.0295 0 0"/>
    <parent link="arm_left_link7"/>
    <child link="arm_left_rokubi_ft_link"/>
  </joint>
  <link name="arm_left_rokubi_ft_wrench_link"/>
  <joint name="arm_left_rokubi_ft_wrench_joint" type="fixed">
    <origin rpy="0 0 0" xyz="0 0 0.032"/>
    <parent link="arm_left_rokubi_ft_link"/>
    <child link="arm_left_rokubi_ft_wrench_link"/>
  </joint>

</robot>
