<?xml version="1.0"?>
<!--
Software License Agreement (BSD)

\file      components.urdf
\authors   Achala Athukorala <chhathuranga@gmail.com>
\copyright Copyright (c) 2024, Singapore University of Technology and Design

Parts of this URDF has been obtained from https://github.com/westonrobot/ugv_gazebo_sim

Redistribution and use in source and binary forms, with or without modification, are permitted provided that
the following conditions are met:
 * Redistributions of source code must retain the above copyright notice, this list of conditions and the
   following disclaimer.
 * Redistributions in binary form must reproduce the above copyright notice, this list of conditions and the
   following disclaimer in the documentation and/or other materials provided with the distribution.
 * Neither the name of Clearpath Robotics nor the names of its contributors may be used to endorse or promote
   products derived from this software without specific prior written permission.

THIS SOFTWARE IS PROVIDED BY THE COPYRIGHT HOLDERS AND CONTRIBUTORS "AS IS" AND ANY EXPRESS OR IMPLIED WAR-
RANTIES, INCLUDING, BUT NOT LIMITED TO, THE IMPLIED WARRANTIES OF MERCHANTABILITY AND FITNESS FOR A PARTICULAR
PURPOSE ARE DISCLAIMED. IN NO EVENT SHALL THE COPYRIGHT HOLDER OR CONTRIBUTORS BE LIABLE FOR ANY DIRECT, IN-
DIRECT, INCIDENTAL, SPECIAL, EXEMPLARY, OR CONSEQUENTIAL DAMAGES (INCLUDING, BUT NOT LIMITED TO, PROCUREMENT
OF SUBSTITUTE GOODS OR SERVICES; LOSS OF USE, DATA, OR PROFITS; OR BUSINESS INTERRUPTION) HOWEVER CAUSED AND
ON ANY THEORY OF LIABILITY, WHETHER IN CONTRACT, STRICT LIABILITY, OR TORT (INCLUDING NEGLIGENCE OR OTHERWISE)
ARISING IN ANY WAY OUT OF THE USE OF THIS SOFTWARE, EVEN IF ADVISED OF THE POSSIBILITY OF SUCH DAMAGE.
-->

<robot xmlns:xacro="http://www.ros.org/wiki/xacro">

    <xacro:include filename="$(find libertech_ranger_arm_description)/urdf/common/gazebo.xacro"/>

    <!-- Robot Base -->
    <xacro:macro name="ranger_mini_v2" params="base_link_name">

        <link name="${base_link_name}">
            <inertial>
                <origin xyz="0.0 0.0 0.0"/>
                <mass value="20"/>
                <inertia ixx="1" ixy="0.0" ixz="0.0" iyy="1" iyz="0.0" izz="1"/>
            </inertial>
            <visual>
                <origin xyz="0 0 0" rpy="1.57 0 3.14 " />
                <geometry>
                    <mesh filename="${mesh_visual_path}/ranger_mini_v2/ranger_base.dae" />
                </geometry>
            </visual>
            <collision>
                <origin xyz="0 0 -0.1" rpy="0 0 0" />
                <geometry>
                    <box size="0.5 0.35 0.2"/>
                </geometry>
            </collision>

        </link>

        <link name="fl_steering_wheel_link">
            <inertial>
                <origin xyz="0.0 0.0 0.0"/>
                <mass value="1"/>
                <inertia ixx="0.01" ixy="0.0" ixz="0.0" iyy="0.01" iyz="0.0" izz="0.01"/>
            </inertial>
            <visual>
                <origin xyz="-0.23 -0.194 0.1" rpy="1.57 0 3.14 " />
                <geometry>
                    <mesh filename="${mesh_visual_path}/ranger_mini_v2/fl.dae" />
                </geometry>
            </visual>
            <collision>
                <origin xyz="0 0 0.008" rpy="0 0 0" />
                <geometry>
                    <cylinder radius="0.001" length="0.001"/>
                </geometry>
            </collision>
        </link>
        <joint name="fl_steering_wheel" type="revolute">
            <origin xyz="0.23 0.206 -0.1" rpy="0 0 0" />
            <parent link="${base_link_name}"/>
            <child link="fl_steering_wheel_link"/>
            <axis xyz="0 0 1" rpy="0 0 0" />
            <limit effort="5" velocity="1" lower="-2.1" upper="2.1" />
        </joint>

        <link name="fl_wheel_link">
            <inertial>
                <mass value="8" />
                <origin xyz="0 0 0" />
                <inertia ixx="0.1171" ixy="0" ixz="0" iyy="0.1361" iyz="0" izz="0.1171" />
            </inertial>
            <visual>
                <origin xyz="0 0 0" rpy="1.57 0 0" />
                <geometry>
                    <cylinder length="0.01" radius="0.01" />
                </geometry>
            </visual>
            <collision>
                <origin xyz="0 0 0" rpy="1.57 0 0" />
                <geometry>
                    <cylinder length="0.08" radius="0.08" />
                </geometry>
                <contact>
                    <ode>
                        <min_depth>0.001</min_depth>
                    </ode>
                </contact>
            </collision>
        </link>

        <joint name="fl_wheel" type="continuous">
            <origin xyz="0.00 0.00 -0.12" rpy="0 0 0" />
            <parent link="fl_steering_wheel_link"/>
            <child link="fl_wheel_link"/>
            <axis xyz="0 1 0" rpy="0 0 0" />
        </joint>


        <link name="fr_steering_wheel_link">
            <inertial>
                <origin xyz="0.0 0.0 0.0" rpy="0.0 0.0 0.0"/>
                <mass value="1"/>
                <inertia ixx="0.01" ixy="0.0" ixz="0.0" iyy="0.01" iyz="0.0" izz="0.01"/>
            </inertial>
            <visual>
                <origin xyz="-0.23 0.194 0.1" rpy="1.57 0 3.14 " />
                <geometry>
                    <mesh filename="${mesh_visual_path}/ranger_mini_v2/fr.dae" />
                </geometry>
            </visual>
            <collision>
                <origin xyz="0 0 0.008" rpy="0 0 0" />
                <geometry>
                    <cylinder radius="0.001" length="0.001"/>
                </geometry>
            </collision>
        </link>
        <joint name="fr_steering_wheel" type="revolute">
            <origin xyz="0.23 -0.206 -0.1" rpy="0 0 0" />
            <parent link="${base_link_name}"/>
            <child link="fr_steering_wheel_link"/>
            <axis xyz="0 0 1" rpy="0 0 0" />
            <limit effort="5" velocity="1" lower="-2.1" upper="2.1" />
        </joint>

        <link name="fr_wheel_link">
            <inertial>
                <mass value="8" />
                <origin xyz="0 0 0" />
                <inertia ixx="0.1171" ixy="0" ixz="0" iyy="0.1361" iyz="0" izz="0.1171" />
            </inertial>
            <visual>
                <origin xyz="0 0 0" rpy="1.57 0 0" />
                <geometry>
                    <cylinder length="0.01" radius="0.01" />
                </geometry>
            </visual>
            <collision>
                <origin xyz="0 0 0" rpy="1.57 0 0" />
                <geometry>
                    <cylinder length="0.08" radius="0.08" />
                </geometry>
                <contact>
                    <ode>
                        <min_depth>0.001</min_depth>
                    </ode>
                </contact>
            </collision>
        </link>

        <joint name="fr_wheel" type="continuous">
            <origin xyz="0.0 0.0 -0.12" rpy="0 0 0" />
            <parent link="fr_steering_wheel_link"/>
            <child link="fr_wheel_link"/>
            <axis xyz="0 1 0" rpy="0 0 0" />
        </joint>


        <link name="rl_steering_wheel_link">
            <inertial>
                <origin xyz="0.0 0.0 0.0" rpy="0.0 0.0 0.0"/>
                <mass value="1"/>
                <inertia ixx="0.01" ixy="0.0" ixz="0.0" iyy="0.01" iyz="0.0" izz="0.01"/>
            </inertial>
            <visual>
                <origin xyz="-0.23 -0.194 0.1" rpy="1.57 0 3.14 " />
                <geometry>
                    <mesh filename="${mesh_visual_path}/ranger_mini_v2/fl.dae" />
                </geometry>
            </visual>
            <collision>
                <origin xyz="0 0 0.008" rpy="0 0 0" />
                <geometry>
                    <cylinder radius="0.001" length="0.001"/>
                </geometry>
            </collision>
        </link>
        <joint name="rl_steering_wheel" type="revolute">
            <origin xyz="-0.23 0.206 -0.1" rpy="0 0 0" />
            <parent link="${base_link_name}"/>
            <child link="rl_steering_wheel_link"/>
            <axis xyz="0 0 1" rpy="0 0 0" />
            <limit effort="5" velocity="1" lower="-2.1" upper="2.1" />
        </joint>


        <link name="rl_wheel_link">
            <inertial>
                <mass value="8" />
                <origin xyz="0 0 0" />
                <inertia ixx="0.1171" ixy="0" ixz="0" iyy="0.1361" iyz="0" izz="0.1171" />
            </inertial>
            <visual>
                <origin xyz="0 0 0" rpy="1.57 0 0" />
                <geometry>
                    <cylinder length="0.01" radius="0.01" />
                </geometry>
            </visual>
            <collision>
                <origin xyz="0 0 0" rpy="1.57 0 0" />
                <geometry>
                    <cylinder length="0.08" radius="0.08" />
                </geometry>
                <contact>
                    <ode>
                        <min_depth>0.001</min_depth>
                    </ode>
                </contact>
            </collision>
        </link>

        <joint name="rl_wheel" type="continuous">
            <origin xyz="0.0 0.0 -0.12 " rpy="0 0 0" />
            <parent link="rl_steering_wheel_link"/>
            <child link="rl_wheel_link"/>
            <axis xyz="0 1 0" rpy="0 0 0" />
        </joint>


        <link name="rr_steering_wheel_link">
            <inertial>
                <origin xyz="0.0 0.0 0.0"/>
                <mass value="1"/>
                <inertia ixx="0.01" ixy="0.0" ixz="0.0" iyy="0.01" iyz="0.0" izz="0.01"/>
            </inertial>
            <visual>
                <origin xyz="-0.23 0.194 0.1" rpy="1.57 0 3.14 " />
                <geometry>
                    <mesh filename="${mesh_visual_path}/ranger_mini_v2/fr.dae" />
                </geometry>
            </visual>
            <collision>
                <origin xyz="0 0 0.008" rpy="0 0 0" />
                <geometry>
                    <cylinder radius="0.001" length="0.001"/>
                </geometry>
            </collision>
        </link>
        <joint name="rr_steering_wheel" type="revolute">
            <origin xyz="-0.23 -0.206 -0.1" rpy="0 0 0" />
            <parent link="${base_link_name}"/>
            <child link="rr_steering_wheel_link"/>
            <axis xyz="0 0 1" rpy="0 0 0" />
            <limit effort="5" velocity="1" lower="-2.1" upper="2.1" />
        </joint>

        <link name="rr_wheel_link">
            <inertial>
                <mass value="8" />
                <origin xyz="0 0 0" />
                <inertia ixx="0.1171" ixy="0" ixz="0" iyy="0.1361" iyz="0" izz="0.1171" />
            </inertial>
            <visual>
                <origin xyz="0.0 0.0 0.0" rpy="1.57 0 0" />
                <geometry>
                    <cylinder length="0.01" radius="0.01" />
                </geometry>
            </visual>
            <collision>
                <origin xyz="0 0 0" rpy="1.57 0 0" />
                <geometry>
                    <cylinder length="0.08" radius="0.08" />
                </geometry>
                <contact>
                    <ode>
                        <min_depth>0.001</min_depth>
                    </ode>
                </contact>
            </collision>
        </link>

        <joint name="rr_wheel" type="continuous">
            <origin xyz="0.0 0.0 -0.12 " rpy="0 0 0" />
            <parent link="rr_steering_wheel_link"/>
            <child link="rr_wheel_link"/>
            <axis xyz="0 1 0" rpy="0 0 0" />
        </joint>

        <xacro:gazebo_link link_name="fl_wheel_link"/>
        <xacro:gazebo_link link_name="fr_wheel_link"/>
        <xacro:gazebo_link link_name="rl_wheel_link"/>
        <xacro:gazebo_link link_name="rr_wheel_link"/>

    </xacro:macro>

</robot>


